Workbook

Sheet 1st Qtr
A1: Week 1 | E1: Week 2 | I1: Week 3 | M1: Week 4 | Q1: Week 5 | U1: Week 6 | Y1: Week 7 | AC1: Week 8 | AG1: Week 9
A2: CASH | E2: CASH | I2: CASH | M2: CASH | Q2: CASH | U2: CASH | Y2: CASH | AC2: CASH | AG2: CASH
A3: 1 | B3: 25 | C3: =+A3*B3 -> 25 | E3: 1 | F3: 25 | G3: =+E3*F3 -> 25 | I3: 1 | J3: 3.5 | K3: =+I3*J3 -> 3.5 | M3: 1 | N3: 24.25 | O3: =+M3*N3 -> 24.25 | Q3: 1 | R3: 20 | S3: =+Q3*R3 -> 20 | U3: 1 | V3: 30 | W3: =+U3*V3 -> 30 | Y3: 1 | Z3: 0 | AA3: =+Y3*Z3 -> 0 | AC3: 1 | AD3: 20 | AE3: =+AC3*AD3 -> 20 | AG3: 1 | AH3: 4 | AI3: 5
A4: 5 | B4: 15 | C4: =+A4*B4 -> 75 | E4: 5 | F4: 22 | G4: =+E4*F4 -> 110 | I4: 5 | J4: 24 | K4: =+I4*J4 -> 120 | M4: 5 | N4: 12 | O4: =+M4*N4 -> 60 | Q4: 5 | R4: 6 | S4: =+Q4*R4 -> 30 | U4: 5 | V4: 39 | W4: =+U4*V4 -> 195 | Y4: 5 | Z4: 10 | AA4: =+Y4*Z4 -> 50 | AC4: 5 | AD4: 14 | AE4: =+AC4*AD4 -> 70 | AG4: 5 | AH4: 9 | AI4: =+AG4*AH4 -> 45
A5: 10 | B5: 18 | C5: =+A5*B5 -> 180 | E5: 10 | F5: 6 | G5: =+E5*F5 -> 60 | I5: 10 | J5: 15 | K5: =+I5*J5 -> 150 | M5: 10 | N5: 9 | O5: =+M5*N5 -> 90 | Q5: 10 | R5: 8 | S5: =+Q5*R5 -> 80 | U5: 10 | V5: 9 | W5: =+U5*V5 -> 90 | Y5: 10 | Z5: 16 | AA5: =+Y5*Z5 -> 160 | AC5: 10 | AD5: 11 | AE5: =+AC5*AD5 -> 110 | AG5: 10 | AH5: 6 | AI5: =+AG5*AH5 -> 60
A6: 20 | B6: 82 | C6: =+A6*B6 -> 1640 | E6: 20 | F6: 48 | G6: =+E6*F6 -> 960 | I6: 20 | J6: 66 | K6: =+I6*J6 -> 1320 | M6: 20 | N6: 68 | O6: =+M6*N6 -> 1360 | Q6: 20 | R6: 47 | S6: =+Q6*R6 -> 940 | U6: 20 | V6: 68 | W6: =+U6*V6 -> 1360 | Y6: 20 | Z6: 38 | AA6: =+Y6*Z6 -> 760 | AC6: 20 | AD6: 90 | AE6: =+AC6*AD6 -> 1800 | AG6: 20 | AH6: 45 | AI6: =+AG6*AH6 -> 900
A7: 20 | C7: =+A7*B7 -> 0 | E7: 20 | F7: 0 | G7: =+E7*F7 -> 0 | I7: 20 | J7: 0 | K7: =+I7*J7 -> 0 | M7: 20 | O7: =+M7*N7 -> 0 | Q7: 20 | R7: 0 | S7: =+Q7*R7 -> 0 | U7: 20 | V7: 0 | W7: =+U7*V7 -> 0 | Y7: 20 | Z7: 0 | AA7: =+Y7*Z7 -> 0 | AC7: 20 | AD7: 0 | AE7: =+AC7*AD7 -> 0 | AG7: 20 | AH7: 0 | AI7: =+AG7*AH7 -> 0
A8: 50 | B8: 1 | C8: =+A8*B8 -> 50 | E8: 50 | F8: 1 | G8: =+E8*F8 -> 50 | I8: 50 | J8: 2 | K8: =+I8*J8 -> 100 | M8: 50 | N8: 1 | O8: =+M8*N8 -> 50 | Q8: 50 | R8: 2 | S8: =+Q8*R8 -> 100 | U8: 50 | V8: 3 | W8: =+U8*V8 -> 150 | Y8: 50 | Z8: 0 | AA8: =+Y8*Z8 -> 0 | AC8: 50 | AD8: 2 | AE8: =+AC8*AD8 -> 100 | AG8: 50 | AH8: 0 | AI8: =+AG8*AH8 -> 0
A9: 100 | B9: 10 | C9: =+A9*B9 -> 1000 | E9: 100 | F9: 4 | G9: =+E9*F9 -> 400 | I9: 100 | J9: 4 | K9: =+I9*J9 -> 400 | M9: 100 | N9: 22 | O9: =+M9*N9 -> 2200 | Q9: 100 | R9: 6 | S9: =+Q9*R9 -> 600 | U9: 100 | V9: 1 | W9: =+U9*V9 -> 100 | Y9: 100 | Z9: 1 | AA9: =+Y9*Z9 -> 100 | AC9: 100 | AD9: 8 | AE9: =+AC9*AD9 -> 800 | AG9: 100 | AH9: 3 | AI9: =+AG9*AH9 -> 300 | AO9: 5
B10: Total | C10: =SUM(C3:C9) -> 2970 | F10: Total | G10: =SUM(G3:G9) -> 1605 | J10: Total | K10: =SUM(K3:K9) -> 2093.5 | N10: Total | O10: =SUM(O3:O9) -> 3784.25 | R10: Total | S10: =SUM(S3:S9) -> 1770 | V10: Total | W10: =SUM(W3:W9) -> 1925 | Z10: Total | AA10: =SUM(AA3:AA9) -> 1070 | AD10: Total | AE10: =SUM(AE3:AE9) -> 2900 | AH10: Total | AI10: =SUM(AI3:AI9) -> 1310 | AO10: 45
A11: Checks | E11: Checks | I11: Checks | M11: Checks | Q11: Checks | U11: Checks | Y11: Checks | AC11: Checks | AG11: Checks | AO11: 60
A12: 30 | B12: 1 | C12: =+A12*B12 -> 30 | E12: 30 | F12: 1 | G12: =+E12*F12 -> 30 | I12: 30 | J12: 1 | K12: =+I12*J12 -> 30 | M12: 30 | N12: 3 | O12: =+M12*N12 -> 90 | Q12: 30 | R12: 2 | S12: =+Q12*R12 -> 60 | U12: 30 | V12: 2 | W12: =+U12*V12 -> 60 | Y12: 30 | Z12: 0 | AA12: =+Y12*Z12 -> 0 | AC12: 30 | AD12: 0 | AE12: =+AC12*AD12 -> 0 | AG12: 30 | AH12: 0 | AI12: =+AG12*AH12 -> 0 | AO12: 900
A13: 60 | B13: 3 | C13: =+A13*B13 -> 180 | E13: 60 | F13: 1 | G13: =+E13*F13 -> 60 | I13: 60 | J13: 3 | K13: =+I13*J13 -> 180 | M13: 60 | N13: 1 | O13: =+M13*N13 -> 60 | Q13: 60 | R13: 1 | S13: =+Q13*R13 -> 60 | U13: 60 | V13: 0 | W13: =+U13*V13 -> 0 | Y13: 60 | Z13: 1 | AA13: =+Y13*Z13 -> 60 | AC13: 60 | AD13: 1 | AE13: =+AC13*AD13 -> 60 | AG13: 60 | AH13: 0 | AI13: =+AG13*AH13 -> 0 | AO13: 300
A14: 90 | B14: 0 | C14: =+A14*B14 -> 0 | E14: 90 | F14: 1 | G14: =+E14*F14 -> 90 | I14: 90 | J14: 1 | K14: =+I14*J14 -> 90 | M14: 90 | N14: 0 | O14: =+M14*N14 -> 0 | Q14: 90 | R14: 1 | S14: =+Q14*R14 -> 90 | U14: 90 | V14: 1 | W14: =+U14*V14 -> 90 | Y14: 90 | Z14: 0 | AA14: =+Y14*Z14 -> 0 | AC14: 90 | AD14: 0 | AE14: =+AC14*AD14 -> 0 | AG14: 90 | AH14: 0 | AI14: =+AG14*AH14 -> 0 | AO14: 120
A15: 120 | B15: 1 | C15: =+A15*B15 -> 120 | E15: 140 | F15: 1 | G15: =+E15*F15 -> 140 | I15: 120 | J15: 1 | K15: =+I15*J15 -> 120 | M15: 120 | N15: 1 | O15: =+M15*N15 -> 120 | Q15: 120 | R15: 1 | S15: =+Q15*R15 -> 120 | U15: 120 | V15: 1 | W15: =+U15*V15 -> 120 | Y15: 120 | Z15: 1 | AA15: =+Y15*Z15 -> 120 | AC15: 120 | AD15: 0 | AE15: =+AC15*AD15 -> 0 | AG15: 120 | AH15: 1 | AI15: =+AG15*AH15 -> 120 | AO15: 150
A16: 210 | B16: 1 | C16: =+A16*B16 -> 210 | G16: =+E16*F16 -> 0 | I16: 150 | J16: 1 | K16: =+I16*J16 -> 150 | L16: 140 | M16: 140 | N16: 1 | O16: =+M16*N16 -> 140 | Q16: 500.25 | R16: 3 | S16: =+Q16*R16 -> 1500.75 | U16: 140 | V16: 1 | W16: =+U16*V16 -> 140 | Y16: 590 | Z16: 1 | AA16: =+Y16*Z16 -> 590 | AC16: 150 | AD16: 1 | AE16: =+AC16*AD16 -> 150 | AG16: 150 | AH16: 1 | AI16: =+AG16*AH16 -> 150 | AO16: =SUM(AO9:AO15) -> 1580
A17: 300 | B17: 1 | C17: =+A17*B17 -> 300 | F17: 0 | G17: =+E17*F17 -> 0 | J17: 0 | K17: =+I17*J17 -> 0 | M17: 240 | N17: 1 | O17: =+M17*N17 -> 240 | Q17: 35 | R17: 1 | S17: =+Q17*R17 -> 35 | U17: 300 | V17: 1 | W17: =+U17*V17 -> 300 | Z17: 0 | AA17: =+Y17*Z17 -> 0 | AC17: 180 | AD17: 1 | AE17: =+AC17*AD17 -> 180 | AH17: 0 | AI17: =+AG17*AH17 -> 0 | AO17: 280
A18: 500 | B18: 1 | C18: =+A18*B18 -> 500 | F18: 0 | G18: =+E18*F18 -> 0 | J18: 0 | K18: =+I18*J18 -> 0 | N18: 0 | O18: =+M18*N18 -> 0 | R18: 0 | S18: =+Q18*R18 -> 0 | U18: 500.25 | V18: 1 | W18: =+U18*V18 -> 500.25 | Z18: 0 | AA18: =+Y18*Z18 -> 0 | AD18: 0 | AE18: =+AC18*AD18 -> 0 | AH18: 1 | AI18: =+AG18*AH18 -> 0 | AO18: =SUM(AO16:AO17) -> 1860
B19: 0 | C19: =+A19*B19 -> 0 | F19: 0 | G19: =+E19*F19 -> 0 | J19: 0 | K19: =+I19*J19 -> 0 | N19: 0 | O19: =+M19*N19 -> 0 | R19: 0 | S19: =+Q19*R19 -> 0 | V19: 0 | W19: =+U19*V19 -> 0 | Z19: 0 | AA19: =+Y19*Z19 -> 0 | AD19: 0 | AE19: =+AC19*AD19 -> 0 | AH19: 0 | AI19: =+AG19*AH19 -> 0
B20: 0 | C20: =+A20*B20 -> 0 | F20: 0 | G20: =+E20*F20 -> 0 | J20: 0 | K20: =+I20*J20 -> 0 | N20: 0 | O20: =+M20*N20 -> 0 | R20: 0 | S20: =+Q20*R20 -> 0 | V20: 0 | W20: =+U20*V20 -> 0 | Z20: 0 | AA20: =+Y20*Z20 -> 0 | AD20: 0 | AE20: =+AC20*AD20 -> 0 | AH20: 0 | AI20: =+AG20*AH20 -> 0
B21: 0 | C21: =+A21*B21 -> 0 | F21: 0 | G21: =+E21*F21 -> 0 | J21: 0 | K21: =+I21*J21 -> 0 | N21: 0 | O21: =+M21*N21 -> 0 | R21: 0 | S21: =+Q21*R21 -> 0 | V21: 0 | W21: =+U21*V21 -> 0 | Z21: 0 | AA21: =+Y21*Z21 -> 0 | AD21: 0 | AE21: =+AC21*AD21 -> 0 | AH21: 0 | AI21: =+AG21*AH21 -> 0
B22: Total | C22: =SUM(C12:C21) -> 1340 | F22: Total | G22: =SUM(G12:G21) -> 320 | J22: Total | K22: =SUM(K12:K21) -> 570 | N22: Total | O22: =SUM(O12:O21) -> 650 | R22: Total | S22: =SUM(S12:S21) -> 1865.75 | V22: Total | W22: =SUM(W12:W21) -> 1210.25 | Z22: Total | AA22: =SUM(AA12:AA21) -> 770 | AD22: Total | AE22: =SUM(AE12:AE21) -> 390 | AH22: Total | AI22: =SUM(AI12:AI21) -> 270
A23: 50/50 Collected | C23: 55 | E23: 50/50 Collected | G23: 52 | I23: 50/50 Collected | K23: 64 | M23: 50/50 Collected | O23: 52 | Q23: 50/50 Collected | S23: 62 | U23: 50/50 Collected | W23: 63 | Y23: 50/50 Collected | AA23: 75 | AC23: 50/50 Collected | AE23: 65 | AG23: 50/50 Collected | AI23: 0
A24: Lineage | C24: 967.25 | E24: Lineage | G24: 1060 | I24: Lineage | K24: 1139.5 | M24: Lineage | O24: =+O32*13.25 -> 1192.5 | Q24: Lineage | S24: =+S32*13.25 -> 1192.5 | U24: Lineage | W24: =+W32*13.25 -> 1113 | Y24: Lineage | AA24: =+AA32*13.25 -> 1113 | AC24: Lineage | AE24: =+AE32*13.25 -> 1046.75 | AF24: =+AL28 -> 0 | AG24: Lineage | AI24: =+AI32*13.25 -> 1046.75
A25: Vegas Rooms | C25: ='1'!G27+'2'!G27+'3'!G27+'4'!G27+'5'!G27+'6'!G27+'7'!G27+'8'!G27+'9'!G27+'10'!G27+'11'!G27+'12'!G27+'13'!G27+'14'!G27+'15'!G27+'16'!G27+'17'!G27+'18'!G27+'19'!G27+'20'!G27 -> 0 | E25: Vegas Rooms | G25: ='1'!G27+'2'!G27+'3'!G27+'4'!G27+'5'!G27+'6'!G27+'7'!G27+'8'!G27+'9'!G27+'10'!G27+'11'!G27+'12'!G27+'13'!G27+'14'!G27+'15'!G27+'16'!G27+'17'!G27+'18'!G27+'19'!G27+'20'!G27 -> 0 | I25: Vegas Rooms | K25: ='1'!G27+'2'!G27+'3'!G27+'4'!G27+'5'!G27+'6'!G27+'7'!G27+'8'!G27+'9'!G27+'10'!G27+'11'!G27+'12'!G27+'13'!G27+'14'!G27+'15'!G27+'16'!G27+'17'!G27+'18'!G27+'19'!G27+'20'!G27 -> 0 | M25: Vegas Rooms | O25: ='1'!G27+'2'!G27+'3'!G27+'4'!G27+'5'!G27+'6'!G27+'7'!G27+'8'!G27+'9'!G27+'10'!G27+'11'!G27+'12'!G27+'13'!G27+'14'!G27+'15'!G27+'16'!G27+'17'!G27+'18'!G27+'19'!G27+'20'!G27 -> 0 | Q25: Vegas Rooms | S25: ='1'!G27+'2'!G27+'3'!G27+'4'!G27+'5'!G27+'6'!G27+'7'!G27+'8'!G27+'9'!G27+'10'!G27+'11'!G27+'12'!G27+'13'!G27+'14'!G27+'15'!G27+'16'!G27+'17'!G27+'18'!G27+'19'!G27+'20'!G27 -> 0 | U25: Vegas Rooms | W25: ='1'!G27+'2'!G27+'3'!G27+'4'!G27+'5'!G27+'6'!G27+'7'!G27+'8'!G27+'9'!G27+'10'!G27+'11'!G27+'12'!G27+'13'!G27+'14'!G27+'15'!G27+'16'!G27+'17'!G27+'18'!G27+'19'!G27+'20'!G27 -> 0 | Y25: Vegas Rooms | AA25: ='1'!G27+'2'!G27+'3'!G27+'4'!G27+'5'!G27+'6'!G27+'7'!G27+'8'!G27+'9'!G27+'10'!G27+'11'!G27+'12'!G27+'13'!G27+'14'!G27+'15'!G27+'16'!G27+'17'!G27+'18'!G27+'19'!G27+'20'!G27 -> 0 | AC25: Vegas Rooms | AE25: ='1'!G27+'2'!G27+'3'!G27+'4'!G27+'5'!G27+'6'!G27+'7'!G27+'8'!G27+'9'!G27+'10'!G27+'11'!G27+'12'!G27+'13'!G27+'14'!G27+'15'!G27+'16'!G27+'17'!G27+'18'!G27+'19'!G27+'20'!G27 -> 0 | AG25: Vegas Rooms | AI25: ='1'!G27+'2'!G27+'3'!G27+'4'!G27+'5'!G27+'6'!G27+'7'!G27+'8'!G27+'9'!G27+'10'!G27+'11'!G27+'12'!G27+'13'!G27+'14'!G27+'15'!G27+'16'!G27+'17'!G27+'18'!G27+'19'!G27+'20'!G27 -> 0
A26: Deposit Total | C26: =+C10+C22+C23-C24+C25 -> 3397.75 | E26: Deposit Total | G26: =+G10+G22+G23+G25 -> 1977 | I26: Deposit Total | K26: =+K10+K22+K23+K25 -> 2727.5 | M26: Deposit Total | O26: =+O10+O22+O23+O25 -> 4486.25 | Q26: Deposit Total | S26: =+S10+S22+S23+S25 -> 3697.75 | U26: Deposit Total | W26: =+W10+W22+W23+W25 -> 3198.25 | Y26: Deposit Total | AA26: =+AA10+AA22+AA23+AA25 -> 1915 | AC26: Deposit Total | AE26: =+AE10+AE22+AE23+AE25 -> 3355 | AG26: Deposit Total | AI26: =+AI10+AI22+AI23+AI25 -> 1580
A28: =A1 -> Week 1 | C28: =+'1'!B9+'2'!B9+'3'!B9+'4'!B9+'5'!B9+'6'!B9+'7'!B9+'8'!B9+'9'!B9+'10'!B9+'11'!B9+'12'!B9+'13'!B9+'14'!B9+'15'!B9+'16'!B9+'17'!B9+'18'!B9+'19'!B9+'20'!B9 -> 4340 | E28: =E1 -> Week 2 | G28: =+'1'!C9+'2'!C9+'3'!C9+'4'!C9+'5'!C9+'6'!C9+'7'!C9+'8'!C9+'9'!C9+'10'!C9+'11'!C9+'12'!C9+'13'!C9+'14'!C9+'15'!C9+'16'!C9+'17'!C9+'18'!C9+'19'!C9+'20'!C9 -> 2085 | I28: =I1 -> Week 3 | K28: =+'1'!D9+'2'!D9+'3'!D9+'4'!D9+'5'!D9+'6'!D9+'7'!D9+'8'!D9+'9'!D9+'10'!D9+'11'!D9+'12'!D9+'13'!D9+'14'!D9+'15'!D9+'16'!D9+'17'!D9+'18'!D9+'19'!D9+'20'!D9 -> 2655.5 | M28: =M1 -> Week 4 | O28: =+'1'!E9+'2'!E9+'3'!E9+'4'!E9+'5'!E9+'6'!E9+'7'!E9+'8'!E9+'9'!E9+'10'!E9+'11'!E9+'12'!E9+'13'!E9+'14'!E9+'15'!E9+'16'!E9+'17'!E9+'18'!E9+'19'!E9+'20'!E9 -> 4584.25 | Q28: =Q1 -> Week 5 | S28: =+'1'!F9+'2'!F9+'3'!F9+'4'!F9+'5'!F9+'6'!F9+'7'!F9+'8'!F9+'9'!F9+'10'!F9+'11'!F9+'12'!F9+'13'!F9+'14'!F9+'15'!F9+'16'!F9+'17'!F9+'18'!F9+'19'!F9+'20'!F9 -> 3665.75 | U28: =U1 -> Week 6 | W28: =+'1'!G9+'2'!G9+'3'!G9+'4'!G9+'5'!G9+'6'!G9+'7'!G9+'8'!G9+'9'!G9+'10'!G9+'11'!G9+'12'!G9+'13'!G9+'14'!G9+'15'!G9+'16'!G9+'17'!G9+'18'!G9+'19'!G9+'20'!G9 -> 3165.25 | Y28: =Y1 -> Week 7 | AA28: =+'1'!H9+'2'!H9+'3'!H9+'4'!H9+'5'!H9+'6'!H9+'7'!H9+'8'!H9+'9'!H9+'10'!H9+'11'!H9+'12'!H9+'13'!H9+'14'!H9+'15'!H9+'16'!H9+'17'!H9+'18'!H9+'19'!H9+'20'!H9 -> 1840 | AC28: =AC1 -> Week 8 | AE28: =+'1'!I9+'2'!I9+'3'!I9+'4'!I9+'5'!I9+'6'!I9+'7'!I9+'8'!I9+'9'!I9+'10'!I9+'11'!I9+'12'!I9+'13'!I9+'14'!I9+'15'!I9+'16'!I9+'17'!I9+'18'!I9+'19'!I9+'20'!I9 -> 3290 | AG28: =AG1 -> Week 9 | AI28: =+'1'!J9+'2'!J9+'3'!J9+'4'!J9+'5'!J9+'6'!J9+'7'!J9+'8'!J9+'9'!J9+'10'!J9+'11'!J9+'12'!J9+'13'!J9+'14'!J9+'15'!J9+'16'!J9+'17'!J9+'18'!J9+'19'!J9+'20'!J9 -> 1760
A29: Diff | C29: =+C26-C28 -> -942.25 | E29: Diff | G29: =+G26-G28 -> -108 | I29: Diff | K29: =+K26-K28 -> 72 | M29: Diff | O29: =+O26-O28 -> -98 | Q29: Diff | S29: =+S26-S28 -> 32 | U29: Diff | W29: =+W26-W28 -> 33 | Y29: Diff | AA29: =+AA26-AA28 -> 75 | AC29: Diff | AE29: =+AE26-AE28 -> 65 | AG29: Diff | AI29: =+AI26-AI28 -> -180
A32: # of Bowlers | C32: 73 | E32: # of Bowlers | G32: 80 | I32: # of Bowlers | K32: 86 | M32: # of Bowlers | O32: 90 | Q32: # of Bowlers | S32: 90 | U32: # of Bowlers | W32: 84 | Y32: # of Bowlers | AA32: 84 | AC32: # of Bowlers | AE32: 79 | AG32: # of Bowlers | AI32: 79

Sheet 2nd Qtr
A1: Week 10 | E1: Week 11 | I1: Week 12 | M1: Week 13 | Q1: Week 14 | U1: Week 15 | Y1: Week 16 | AC1: Week 17 | AG1: Week 18
A2: CASH | E2: CASH | I2: CASH | M2: CASH | Q2: CASH | U2: CASH | Y2: CASH | AC2: CASH | AG2: CASH
A3: 1 | B3: 0 | C3: =+A3*B3 -> 0 | E3: 1 | F3: 0 | G3: =+E3*F3 -> 0 | I3: 1 | J3: 15 | K3: =+I3*J3 -> 15 | M3: 1 | N3: 0 | O3: =+M3*N3 -> 0 | Q3: 1 | R3: 20 | S3: =+Q3*R3 -> 20 | U3: 1 | V3: 0 | W3: =+U3*V3 -> 0 | Y3: 1 | Z3: 0 | AA3: =+Y3*Z3 -> 0 | AC3: 1 | AD3: 15 | AE3: =+AC3*AD3 -> 15 | AG3: 1 | AH3: 0 | AI3: =+AG3*AH3 -> 0
A4: 5 | B4: 14 | C4: =+A4*B4 -> 70 | E4: 5 | F4: 8 | G4: =+E4*F4 -> 40 | I4: 5 | J4: 6 | K4: =+I4*J4 -> 30 | M4: 5 | N4: 9 | O4: =+M4*N4 -> 45 | Q4: 5 | R4: 12 | S4: =+Q4*R4 -> 60 | U4: 5 | V4: 0 | W4: =+U4*V4 -> 0 | Y4: 5 | Z4: 0 | AA4: =+Y4*Z4 -> 0 | AC4: 5 | AD4: 13 | AE4: =+AC4*AD4 -> 65 | AG4: 5 | AH4: 15 | AI4: =+AG4*AH4 -> 75
A5: 10 | B5: 4 | C5: =+A5*B5 -> 40 | E5: 10 | F5: 5 | G5: =+E5*F5 -> 50 | I5: 10 | J5: 3 | K5: =+I5*J5 -> 30 | M5: 10 | N5: 4 | O5: =+M5*N5 -> 40 | Q5: 10 | R5: 5 | S5: =+Q5*R5 -> 50 | U5: 10 | V5: 0 | W5: =+U5*V5 -> 0 | Y5: 10 | Z5: 0 | AA5: =+Y5*Z5 -> 0 | AC5: 10 | AD5: 5 | AE5: =+AC5*AD5 -> 50 | AG5: 10 | AH5: 4 | AI5: =+AG5*AH5 -> 40
A6: 20 | B6: 77 | C6: =+A6*B6 -> 1540 | E6: 20 | F6: 39 | G6: =+E6*F6 -> 780 | I6: 20 | J6: 29 | K6: =+I6*J6 -> 580 | M6: 20 | N6: 0 | O6: =+M6*N6 -> 0 | Q6: 20 | R6: 73 | S6: =+Q6*R6 -> 1460 | U6: 20 | V6: 0 | W6: =+U6*V6 -> 0 | Y6: 20 | Z6: 0 | AA6: =+Y6*Z6 -> 0 | AC6: 20 | AD6: 37 | AE6: =+AC6*AD6 -> 740 | AG6: 20 | AH6: 45 | AI6: =+AG6*AH6 -> 900
A7: 20 | B7: 0 | C7: =+A7*B7 -> 0 | E7: 20 | F7: 0 | G7: =+E7*F7 -> 0 | I7: 20 | J7: 0 | K7: =+I7*J7 -> 0 | M7: 20 | N7: 25 | O7: =+M7*N7 -> 500 | Q7: 20 | R7: 0 | S7: =+Q7*R7 -> 0 | U7: 20 | V7: 0 | W7: =+U7*V7 -> 0 | Y7: 20 | Z7: 0 | AA7: =+Y7*Z7 -> 0 | AC7: 20 | AD7: 0 | AE7: =+AC7*AD7 -> 0 | AG7: 20 | AH7: 0 | AI7: =+AG7*AH7 -> 0
A8: 50 | B8: 0 | C8: =+A8*B8 -> 0 | E8: 50 | F8: 2 | G8: =+E8*F8 -> 100 | I8: 50 | J8: 1 | K8: =+I8*J8 -> 50 | M8: 50 | N8: 4 | O8: =+M8*N8 -> 200 | Q8: 50 | R8: 0 | S8: =+Q8*R8 -> 0 | U8: 50 | V8: 0 | W8: =+U8*V8 -> 0 | Y8: 50 | Z8: 0 | AA8: =+Y8*Z8 -> 0 | AC8: 50 | AD8: 1 | AE8: =+AC8*AD8 -> 50 | AG8: 50 | AH8: 1 | AI8: =+AG8*AH8 -> 50
A9: 100 | B9: 1 | C9: =+A9*B9 -> 100 | E9: 100 | F9: 3 | G9: =+E9*F9 -> 300 | I9: 100 | J9: 0 | K9: =+I9*J9 -> 0 | M9: 100 | N9: 0 | O9: =+M9*N9 -> 0 | Q9: 100 | R9: 1 | S9: =+Q9*R9 -> 100 | U9: 100 | V9: 0 | W9: =+U9*V9 -> 0 | Y9: 100 | Z9: 0 | AA9: =+Y9*Z9 -> 0 | AC9: 100 | AD9: 3 | AE9: =+AC9*AD9 -> 300 | AG9: 100 | AH9: 1 | AI9: =+AG9*AH9 -> 100
B10: Total | C10: =SUM(C3:C9) -> 1750 | F10: Total | G10: =SUM(G3:G9) -> 1270 | J10: Total | K10: =SUM(K3:K9) -> 705 | N10: Total | O10: =SUM(O3:O9) -> 785 | R10: Total | S10: =SUM(S3:S9) -> 1690 | V10: Total | W10: =SUM(W3:W9) -> 0 | Z10: Total | AA10: =SUM(AA3:AA9) -> 0 | AD10: Total | AE10: =SUM(AE3:AE9) -> 1220 | AH10: Total | AI10: =SUM(AI3:AI9) -> 1165
A11: Checks | E11: Checks | I11: Checks | M11: Checks | Q11: Checks | U11: Checks | Y11: Checks | AC11: Checks | AG11: Checks
A12: 30 | B12: 0 | C12: =+A12*B12 -> 0 | E12: 30 | F12: 0 | G12: =+E12*F12 -> 0 | I12: 30 | J12: 0 | K12: =+I12*J12 -> 0 | M12: 30 | N12: 0 | O12: =+M12*N12 -> 0 | Q12: 30 | R12: 0 | S12: =+Q12*R12 -> 0 | U12: 30 | V12: 0 | W12: =+U12*V12 -> 0 | Y12: 30 | Z12: 0 | AA12: =+Y12*Z12 -> 0 | AC12: 30 | AD12: 0 | AE12: =+AC12*AD12 -> 0 | AG12: 30 | AH12: 1 | AI12: =+AG12*AH12 -> 30
A13: 60 | B13: 0 | C13: =+A13*B13 -> 0 | E13: 60 | F13: 3 | G13: =+E13*F13 -> 180 | I13: 60 | J13: 0 | K13: =+I13*J13 -> 0 | M13: 60 | N13: 3 | O13: =+M13*N13 -> 180 | Q13: 60 | R13: 0 | S13: =+Q13*R13 -> 0 | U13: 60 | V13: 0 | W13: =+U13*V13 -> 0 | Y13: 60 | Z13: 0 | AA13: =+Y13*Z13 -> 0 | AC13: 60 | AD13: 4 | AE13: =+AC13*AD13 -> 240 | AG13: 60 | AH13: 1 | AI13: =+AG13*AH13 -> 60
A14: 90 | B14: 0 | C14: =+A14*B14 -> 0 | E14: 90 | F14: 0 | G14: =+E14*F14 -> 0 | I14: 90 | J14: 0 | K14: =+I14*J14 -> 0 | M14: 90 | N14: 0 | O14: =+M14*N14 -> 0 | Q14: 90 | R14: 0 | S14: =+Q14*R14 -> 0 | U14: 90 | V14: 0 | W14: =+U14*V14 -> 0 | Y14: 90 | Z14: 0 | AA14: =+Y14*Z14 -> 0 | AC14: 90 | AD14: 0 | AE14: =+AC14*AD14 -> 0 | AG14: 90 | AH14: 0 | AI14: =+AG14*AH14 -> 0
A15: 120 | C15: =+A15*B15 -> 0 | E15: 120 | F15: 1 | G15: =+E15*F15 -> 120 | I15: 120 | J15: 0 | K15: =+I15*J15 -> 0 | M15: 120 | N15: 0 | O15: =+M15*N15 -> 0 | Q15: 120 | R15: 0 | S15: =+Q15*R15 -> 0 | U15: 120 | V15: 0 | W15: =+U15*V15 -> 0 | Y15: 120 | Z15: 0 | AA15: =+Y15*Z15 -> 0 | AC15: 120 | AD15: 1 | AE15: =+AC15*AD15 -> 120 | AG15: 120 | AH15: 0 | AI15: =+AG15*AH15 -> 0
A16: 140 | B16: 1 | C16: =+A16*B16 -> 140 | F16: 0 | G16: =+E16*F16 -> 0 | I16: 140 | J16: 1 | K16: =+I16*J16 -> 140 | M16: 261 | N16: 1 | O16: =+M16*N16 -> 261 | Q16: 130 | R16: 1 | S16: =+Q16*R16 -> 130 | V16: 0 | W16: =+U16*V16 -> 0 | Z16: 0 | AA16: =+Y16*Z16 -> 0 | AC16: 240 | AD16: 1 | AE16: =+AC16*AD16 -> 240 | AG16: 140 | AH16: 1 | AI16: =+AG16*AH16 -> 140
A17: 30 | B17: 0 | C17: 30 | F17: 0 | G17: =+E17*F17 -> 0 | J17: 0 | K17: =+I17*J17 -> 0 | N17: 0 | O17: =+M17*N17 -> 0 | Q17: 140 | R17: 1 | S17: =+Q17*R17 -> 140 | V17: 0 | W17: =+U17*V17 -> 0 | Z17: 0 | AA17: =+Y17*Z17 -> 0 | AD17: 0 | AE17: =+AC17*AD17 -> 0 | AH17: 0 | AI17: =+AG17*AH17 -> 0
B18: 0 | C18: 0 | F18: 0 | G18: =+E18*F18 -> 0 | J18: 0 | K18: =+I18*J18 -> 0 | N18: 0 | O18: =+M18*N18 -> 0 | R18: 0 | S18: =+Q18*R18 -> 0 | V18: 0 | W18: =+U18*V18 -> 0 | Z18: 0 | AA18: =+Y18*Z18 -> 0 | AD18: 0 | AE18: =+AC18*AD18 -> 0 | AH18: 0 | AI18: =+AG18*AH18 -> 0
B19: 0 | C19: =+A19*B19 -> 0 | F19: 0 | G19: =+E19*F19 -> 0 | J19: 0 | K19: =+I19*J19 -> 0 | N19: 0 | O19: =+M19*N19 -> 0 | R19: 0 | S19: =+Q19*R19 -> 0 | V19: 0 | W19: =+U19*V19 -> 0 | Z19: 0 | AA19: =+Y19*Z19 -> 0 | AE19: =+AC19*AD19 -> 0 | AH19: 0 | AI19: =+AG19*AH19 -> 0
B20: 0 | C20: =+A20*B20 -> 0 | F20: 0 | G20: =+E20*F20 -> 0 | J20: 0 | K20: =+I20*J20 -> 0 | N20: 0 | O20: =+M20*N20 -> 0 | R20: 0 | S20: =+Q20*R20 -> 0 | V20: 0 | W20: =+U20*V20 -> 0 | Z20: 0 | AA20: =+Y20*Z20 -> 0 | AC20: 142 | AD20: 1 | AE20: =+AC20*AD20 -> 142 | AH20: 0 | AI20: =+AG20*AH20 -> 0
B21: 0 | C21: =+A21*B21 -> 0 | E21: 250 | F21: 1 | G21: =+E21*F21 -> 250 | I21: 194 | J21: 1 | K21: =+I21*J21 -> 194 | N21: 0 | O21: =+M21*N21 -> 0 | Q21: 580 | R21: 1 | S21: =+Q21*R21 -> 580 | V21: 0 | W21: =+U21*V21 -> 0 | Z21: 0 | AA21: =+Y21*Z21 -> 0 | AC21: 120 | AD21: 1 | AE21: =+AC21*AD21 -> 120 | AG21: 180 | AH21: 1 | AI21: =+AG21*AH21 -> 180
B22: Total | C22: =SUM(C12:C21) -> 170 | F22: Total | G22: =SUM(G12:G21) -> 550 | J22: Total | K22: =SUM(K12:K21) -> 334 | N22: Total | O22: =SUM(O12:O21) -> 441 | R22: Total | S22: =SUM(S12:S21) -> 850 | V22: Total | W22: =SUM(W12:W21) -> 0 | Z22: Total | AA22: =SUM(AA12:AA21) -> 0 | AD22: Total | AE22: =SUM(AE12:AE21) -> 862 | AH22: Total | AI22: =SUM(AI12:AI21) -> 410
A23: 50/50 Collected | C23: 27 | E23: 50/50 Collected | G23: 0 | I23: 50/50 Collected | K23: 25 | M23: 50/50 Collected | O23: 43 | Q23: 50/50 Collected | S23: 44 | U23: 50/50 Collected | W23: 44 | Y23: 50/50 Collected | AA23: 31 | AC23: 50/50 Collected | AE23: 47 | AG23: 50/50 Collected | AI23: 61
A24: Lineage | C24: =+C32*13.25 -> 1033.5 | E24: Lineage | G24: =+G32*13.25 -> 1033.5 | I24: Lineage | K24: =+K32*13.25 -> 1033.5 | M24: Lineage | O24: =+O32*13.25 -> 1020.25 | Q24: Lineage | S24: =+S32*13.25 -> 1020.25 | U24: Lineage | W24: =+W32*13.25 -> 1020.25 | Y24: Lineage | AA24: =+AA32*13.25 -> 1020.25 | AC24: Lineage | AE24: =+AE32*13.25 -> 1020.25 | AG24: Lineage | AI24: =+AI32*13.25 -> 1020.25
A25: Vegas Rooms | C25: ='1'!G27+'2'!G27+'3'!G27+'4'!G27+'5'!G27+'6'!G27+'7'!G27+'8'!G27+'9'!G27+'10'!G27+'11'!G27+'12'!G27+'13'!G27+'14'!G27+'15'!G27+'16'!G27+'17'!G27+'18'!G27+'19'!G27+'20'!G27 -> 0 | E25: Vegas Rooms | G25: ='1'!G27+'2'!G27+'3'!G27+'4'!G27+'5'!G27+'6'!G27+'7'!G27+'8'!G27+'9'!G27+'10'!G27+'11'!G27+'12'!G27+'13'!G27+'14'!G27+'15'!G27+'16'!G27+'17'!G27+'18'!G27+'19'!G27+'20'!G27 -> 0 | I25: Vegas Rooms | K25: ='1'!G27+'2'!G27+'3'!G27+'4'!G27+'5'!G27+'6'!G27+'7'!G27+'8'!G27+'9'!G27+'10'!G27+'11'!G27+'12'!G27+'13'!G27+'14'!G27+'15'!G27+'16'!G27+'17'!G27+'18'!G27+'19'!G27+'20'!G27 -> 0 | M25: Vegas Rooms | O25: ='1'!G27+'2'!G27+'3'!G27+'4'!G27+'5'!G27+'6'!G27+'7'!G27+'8'!G27+'9'!G27+'10'!G27+'11'!G27+'12'!G27+'13'!G27+'14'!G27+'15'!G27+'16'!G27+'17'!G27+'18'!G27+'19'!G27+'20'!G27 -> 0 | Q25: Vegas Rooms | S25: ='1'!G27+'2'!G27+'3'!G27+'4'!G27+'5'!G27+'6'!G27+'7'!G27+'8'!G27+'9'!G27+'10'!G27+'11'!G27+'12'!G27+'13'!G27+'14'!G27+'15'!G27+'16'!G27+'17'!G27+'18'!G27+'19'!G27+'20'!G27 -> 0 | U25: Vegas Rooms | W25: ='1'!G27+'2'!G27+'3'!G27+'4'!G27+'5'!G27+'6'!G27+'7'!G27+'8'!G27+'9'!G27+'10'!G27+'11'!G27+'12'!G27+'13'!G27+'14'!G27+'15'!G27+'16'!G27+'17'!G27+'18'!G27+'19'!G27+'20'!G27 -> 0 | Y25: Vegas Rooms | AA25: ='1'!G27+'2'!G27+'3'!G27+'4'!G27+'5'!G27+'6'!G27+'7'!G27+'8'!G27+'9'!G27+'10'!G27+'11'!G27+'12'!G27+'13'!G27+'14'!G27+'15'!G27+'16'!G27+'17'!G27+'18'!G27+'19'!G27+'20'!G27 -> 0 | AC25: Vegas Rooms | AE25: ='1'!G27+'2'!G27+'3'!G27+'4'!G27+'5'!G27+'6'!G27+'7'!G27+'8'!G27+'9'!G27+'10'!G27+'11'!G27+'12'!G27+'13'!G27+'14'!G27+'15'!G27+'16'!G27+'17'!G27+'18'!G27+'19'!G27+'20'!G27 -> 0 | AG25: Vegas Rooms | AI25: ='1'!G27+'2'!G27+'3'!G27+'4'!G27+'5'!G27+'6'!G27+'7'!G27+'8'!G27+'9'!G27+'10'!G27+'11'!G27+'12'!G27+'13'!G27+'14'!G27+'15'!G27+'16'!G27+'17'!G27+'18'!G27+'19'!G27+'20'!G27 -> 0
A26: Deposit Total | C26: =+C10+C22+C23+C25 -> 1947 | E26: Deposit Total | G26: =+G10+G22+G23+G25 -> 1820 | I26: Deposit Total | K26: =+K10+K22+K23+K25 -> 1064 | M26: Deposit Total | O26: =+O10+O22+O23+O25 -> 1269 | Q26: Deposit Total | S26: =+S10+S22+S23+S25 -> 2584 | U26: Deposit Total | W26: =+W10+W22+W23+W25 -> 44 | Y26: Deposit Total | AA26: 3 | AC26: Deposit Total | AE26: =+AE10+AE22+AE23+AE25 -> 2129 | AG26: Deposit Total | AI26: =+AI10+AI22+AI23+AI25 -> 1636
O27: []\
A28: =A1 -> Week 10 | C28: =+'1'!K9+'2'!K9+'3'!K9+'4'!K9+'5'!K9+'6'!K9+'7'!K9+'8'!K9+'9'!K9+'10'!K9+'11'!K9+'12'!K9+'13'!K9+'14'!K9+'15'!K9+'16'!K9+'17'!K9+'18'!K9+'19'!K9+'20'!K9 -> 2070 | E28: =E1 -> Week 11 | G28: =+'1'!L9+'2'!L9+'3'!L9+'4'!L9+'5'!L9+'6'!L9+'7'!L9+'8'!L9+'9'!L9+'10'!L9+'11'!L9+'12'!L9+'13'!L9+'14'!L9+'15'!L9+'16'!L9+'17'!L9+'18'!L9+'19'!L9+'20'!L9 -> 1790 | I28: =I1 -> Week 12 | K28: =+'1'!M9+'2'!M9+'3'!M9+'4'!M9+'5'!M9+'6'!M9+'7'!M9+'8'!M9+'9'!M9+'10'!M9+'11'!M9+'12'!M9+'13'!M9+'14'!M9+'15'!M9+'16'!M9+'17'!M9+'18'!M9+'19'!M9+'20'!M9 -> 999 | M28: =M1 -> Week 13 | O28: =+'1'!N9+'2'!N9+'3'!N9+'4'!N9+'5'!N9+'6'!N9+'7'!N9+'8'!N9+'9'!N9+'10'!N9+'11'!N9+'12'!N9+'13'!N9+'14'!N9+'15'!N9+'16'!N9+'17'!N9+'18'!N9+'19'!N9+'20'!N9 -> 1736 | Q28: =Q1 -> Week 14 | S28: =+'1'!O9+'2'!O9+'3'!O9+'4'!O9+'5'!O9+'6'!O9+'7'!O9+'8'!O9+'9'!O9+'10'!O9+'11'!O9+'12'!O9+'13'!O9+'14'!O9+'15'!O9+'16'!O9+'17'!O9+'18'!O9+'19'!O9+'20'!O9 -> 2440 | U28: =U1 -> Week 15 | W28: =+'1'!P9+'2'!P9+'3'!P9+'4'!P9+'5'!P9+'6'!P9+'7'!P9+'8'!P9+'9'!P9+'10'!P9+'11'!P9+'12'!P9+'13'!P9+'14'!P9+'15'!P9+'16'!P9+'17'!P9+'18'!P9+'19'!P9+'20'!P9 -> 1880 | Y28: =Y1 -> Week 16 | AA28: =+'1'!Q9+'2'!Q9+'3'!Q9+'4'!Q9+'5'!Q9+'6'!Q9+'7'!Q9+'8'!Q9+'9'!Q9+'10'!Q9+'11'!Q9+'12'!Q9+'13'!Q9+'14'!Q9+'15'!Q9+'16'!Q9+'17'!Q9+'18'!Q9+'19'!Q9+'20'!Q9 -> 2005 | AC28: =AC1 -> Week 17 | AE28: =+'1'!R9+'2'!R9+'3'!R9+'4'!R9+'5'!R9+'6'!R9+'7'!R9+'8'!R9+'9'!R9+'10'!R9+'11'!R9+'12'!R9+'13'!R9+'14'!R9+'15'!R9+'16'!R9+'17'!R9+'18'!R9+'19'!R9+'20'!R9 -> 1940 | AG28: =AG1 -> Week 18 | AI28: =+'1'!S9+'2'!S9+'3'!S9+'4'!S9+'5'!S9+'6'!S9+'7'!S9+'8'!S9+'9'!S9+'10'!S9+'11'!S9+'12'!S9+'13'!S9+'14'!S9+'15'!S9+'16'!S9+'17'!S9+'18'!S9+'19'!S9+'20'!S9 -> 1575
A29: Diff | C29: =+C26-C28 -> -123 | E29: Diff | G29: =+G26-G28 -> 30 | I29: Diff | K29: =+K26-K28 -> 65 | M29: Diff | O29: =+O26-O28 -> -467 | Q29: Diff | S29: =+S26-S28 -> 144 | U29: Diff | W29: =+W26-W28 -> -1836 | Y29: Diff | AA29: =+AA26-AA28 -> -2002 | AC29: Diff | AE29: =+AE26-AE28 -> 189 | AG29: Diff | AI29: =+AI26-AI28 -> 61
A32: # of Bowlers | C32: 78 | E32: # of Bowlers | G32: 78 | I32: # of Bowlers | K32: 78 | M32: # of Bowlers | O32: 77 | Q32: # of Bowlers | S32: 77 | U32: # of Bowlers | W32: 77 | Y32: # of Bowlers | AA32: 77 | AC32: # of Bowlers | AE32: 77 | AG32: # of Bowlers | AI32: 77
N34: 9+9

Sheet 3rd Qtr
A1: Week 19 | E1: Week 20 | I1: Week 21 | M1: Week 22 | Q1: Week 23 | U1: Week 24 | Y1: Week 25 | AC1: Week 26 | AG1: Week 27
A2: CASH | E2: CASH | I2: CASH | M2: CASH | Q2: CASH | U2: CASH | Y2: CASH | AC2: CASH | AG2: CASH
A3: 1 | B3: 0 | C3: =+A3*B3 -> 0 | E3: 1 | F3: 0 | G3: =+E3*F3 -> 0 | I3: 1 | J3: 0 | K3: =+I3*J3 -> 0 | M3: 1 | N3: 0 | O3: =+M3*N3 -> 0 | Q3: 1 | R3: 0 | S3: =+Q3*R3 -> 0 | U3: 1 | V3: 0 | W3: =+U3*V3 -> 0 | Y3: 1 | Z3: 0 | AA3: =+Y3*Z3 -> 0 | AC3: 1 | AD3: 0 | AE3: =+AC3*AD3 -> 0 | AG3: 1 | AH3: 0 | AI3: =+AG3*AH3 -> 0
A4: 5 | B4: 0 | C4: =+A4*B4 -> 0 | E4: 5 | F4: 0 | G4: =+E4*F4 -> 0 | I4: 5 | J4: 0 | K4: =+I4*J4 -> 0 | M4: 5 | N4: 0 | O4: =+M4*N4 -> 0 | Q4: 5 | R4: 0 | S4: =+Q4*R4 -> 0 | U4: 5 | V4: 0 | W4: =+U4*V4 -> 0 | Y4: 5 | Z4: 0 | AA4: =+Y4*Z4 -> 0 | AC4: 5 | AD4: 0 | AE4: =+AC4*AD4 -> 0 | AG4: 5 | AH4: 0 | AI4: =+AG4*AH4 -> 0
A5: 10 | B5: 0 | C5: =+A5*B5 -> 0 | E5: 10 | F5: 0 | G5: =+E5*F5 -> 0 | I5: 10 | J5: 0 | K5: =+I5*J5 -> 0 | M5: 10 | N5: 0 | O5: =+M5*N5 -> 0 | Q5: 10 | R5: 0 | S5: =+Q5*R5 -> 0 | U5: 10 | V5: 0 | W5: =+U5*V5 -> 0 | Y5: 10 | Z5: 0 | AA5: =+Y5*Z5 -> 0 | AC5: 10 | AD5: 0 | AE5: =+AC5*AD5 -> 0 | AG5: 10 | AH5: 0 | AI5: =+AG5*AH5 -> 0
A6: 20 | B6: 0 | C6: =+A6*B6 -> 0 | E6: 20 | F6: 0 | G6: =+E6*F6 -> 0 | I6: 20 | J6: 0 | K6: =+I6*J6 -> 0 | M6: 20 | N6: 0 | O6: =+M6*N6 -> 0 | Q6: 20 | R6: 0 | S6: =+Q6*R6 -> 0 | U6: 20 | V6: 0 | W6: =+U6*V6 -> 0 | Y6: 20 | Z6: 0 | AA6: =+Y6*Z6 -> 0 | AC6: 20 | AD6: 0 | AE6: =+AC6*AD6 -> 0 | AG6: 20 | AH6: 0 | AI6: =+AG6*AH6 -> 0
A7: 20 | B7: 0 | C7: =+A7*B7 -> 0 | E7: 20 | F7: 0 | G7: =+E7*F7 -> 0 | I7: 20 | J7: 0 | K7: =+I7*J7 -> 0 | M7: 20 | N7: 0 | O7: =+M7*N7 -> 0 | Q7: 20 | R7: 0 | S7: =+Q7*R7 -> 0 | U7: 20 | V7: 0 | W7: =+U7*V7 -> 0 | Y7: 20 | Z7: 0 | AA7: =+Y7*Z7 -> 0 | AC7: 20 | AD7: 0 | AE7: =+AC7*AD7 -> 0 | AG7: 20 | AH7: 0 | AI7: =+AG7*AH7 -> 0
A8: 50 | B8: 0 | C8: =+A8*B8 -> 0 | E8: 50 | F8: 0 | G8: =+E8*F8 -> 0 | I8: 50 | J8: 0 | K8: =+I8*J8 -> 0 | M8: 50 | N8: 0 | O8: =+M8*N8 -> 0 | Q8: 50 | R8: 0 | S8: =+Q8*R8 -> 0 | U8: 50 | V8: 0 | W8: =+U8*V8 -> 0 | Y8: 50 | Z8: 0 | AA8: =+Y8*Z8 -> 0 | AC8: 50 | AD8: 0 | AE8: =+AC8*AD8 -> 0 | AG8: 50 | AH8: 0 | AI8: =+AG8*AH8 -> 0
A9: 100 | B9: 0 | C9: =+A9*B9 -> 0 | E9: 100 | F9: 0 | G9: =+E9*F9 -> 0 | I9: 100 | J9: 0 | K9: =+I9*J9 -> 0 | M9: 100 | N9: 0 | O9: =+M9*N9 -> 0 | Q9: 100 | R9: 0 | S9: =+Q9*R9 -> 0 | U9: 100 | V9: 0 | W9: =+U9*V9 -> 0 | Y9: 100 | Z9: 0 | AA9: =+Y9*Z9 -> 0 | AC9: 100 | AD9: 0 | AE9: =+AC9*AD9 -> 0 | AG9: 100 | AH9: 0 | AI9: =+AG9*AH9 -> 0
B10: Total | C10: =SUM(C3:C9) -> 0 | F10: Total | G10: =SUM(G3:G9) -> 0 | J10: Total | K10: =SUM(K3:K9) -> 0 | N10: Total | O10: =SUM(O3:O9) -> 0 | R10: Total | S10: =SUM(S3:S9) -> 0 | V10: Total | W10: =SUM(W3:W9) -> 0 | Z10: Total | AA10: =SUM(AA3:AA9) -> 0 | AD10: Total | AE10: =SUM(AE3:AE9) -> 0 | AH10: Total | AI10: =SUM(AI3:AI9) -> 0
A11: Checks | E11: Checks | I11: Checks | M11: Checks | Q11: Checks | U11: Checks | Y11: Checks | AC11: Checks | AG11: Checks
A12: 30 | B12: 0 | C12: =+A12*B12 -> 0 | E12: 30 | F12: 0 | G12: =+E12*C12 -> 0 | I12: 30 | J12: 0 | K12: =+I12*J12 -> 0 | M12: 30 | N12: 0 | O12: =+M12*D12 -> 0 | Q12: 30 | R12: 0 | S12: =+Q12*R12 -> 0 | U12: 30 | V12: 0 | W12: =+U12*V12 -> 0 | Y12: 30 | Z12: 0 | AA12: =+Y12*Z12 -> 0 | AC12: 30 | AD12: 0 | AE12: =+AC12*AD12 -> 0 | AG12: 30 | AH12: 0 | AI12: =+AG12*AH12 -> 0
A13: 60 | B13: 0 | C13: =+A13*B13 -> 0 | E13: 60 | F13: 0 | G13: =+E13*C13 -> 0 | I13: 60 | J13: 0 | K13: =+I13*J13 -> 0 | M13: 60 | N13: 0 | O13: =+M13*D13 -> 0 | Q13: 60 | R13: 0 | S13: =+Q13*R13 -> 0 | U13: 60 | V13: 0 | W13: =+U13*V13 -> 0 | Y13: 60 | Z13: 0 | AA13: =+Y13*Z13 -> 0 | AC13: 60 | AD13: 0 | AE13: =+AC13*AD13 -> 0 | AG13: 60 | AH13: 0 | AI13: =+AG13*AH13 -> 0
A14: 90 | B14: 0 | C14: =+A14*B14 -> 0 | E14: 90 | F14: 0 | G14: =+E14*C14 -> 0 | I14: 90 | J14: 0 | K14: =+I14*J14 -> 0 | M14: 90 | N14: 0 | O14: =+M14*D14 -> 0 | Q14: 90 | R14: 0 | S14: =+Q14*R14 -> 0 | U14: 90 | V14: 0 | W14: =+U14*V14 -> 0 | Y14: 90 | Z14: 0 | AA14: =+Y14*Z14 -> 0 | AC14: 90 | AD14: 0 | AE14: =+AC14*AD14 -> 0 | AG14: 90 | AH14: 0 | AI14: =+AG14*AH14 -> 0
A15: 120 | B15: 0 | C15: =+A15*B15 -> 0 | E15: 120 | F15: 0 | G15: =+E15*C15 -> 0 | I15: 120 | J15: 0 | K15: =+I15*J15 -> 0 | M15: 120 | N15: 0 | O15: =+M15*D15 -> 0 | Q15: 120 | R15: 0 | S15: =+Q15*R15 -> 0 | U15: 120 | V15: 0 | W15: =+U15*V15 -> 0 | Y15: 120 | Z15: 0 | AA15: =+Y15*Z15 -> 0 | AC15: 120 | AD15: 0 | AE15: =+AC15*AD15 -> 0 | AG15: 120 | AH15: 0 | AI15: =+AG15*AH15 -> 0
B16: 0 | C16: =+A16*B16 -> 0 | F16: 0 | G16: =+E16*C16 -> 0 | J16: 0 | K16: =+I16*J16 -> 0 | N16: 0 | O16: =+M16*D16 -> 0 | R16: 0 | S16: =+Q16*R16 -> 0 | V16: 0 | W16: =+U16*V16 -> 0 | Z16: 0 | AA16: =+Y16*Z16 -> 0 | AD16: 0 | AE16: =+AC16*AD16 -> 0 | AH16: 0 | AI16: =+AG16*AH16 -> 0
B17: 0 | C17: =+A17*B17 -> 0 | F17: 0 | G17: =+E17*C17 -> 0 | J17: 0 | K17: =+I17*J17 -> 0 | N17: 0 | O17: =+M17*D17 -> 0 | R17: 0 | S17: =+Q17*R17 -> 0 | V17: 0 | W17: =+U17*V17 -> 0 | Z17: 0 | AA17: =+Y17*Z17 -> 0 | AD17: 0 | AE17: =+AC17*AD17 -> 0 | AH17: 0 | AI17: =+AG17*AH17 -> 0
B18: 0 | C18: =+A18*B18 -> 0 | F18: 0 | G18: =+E18*C18 -> 0 | J18: 0 | K18: =+I18*J18 -> 0 | N18: 0 | O18: =+M18*D18 -> 0 | R18: 0 | S18: =+Q18*R18 -> 0 | V18: 0 | W18: =+U18*V18 -> 0 | Z18: 0 | AA18: =+Y18*Z18 -> 0 | AD18: 0 | AE18: =+AC18*AD18 -> 0 | AH18: 0 | AI18: =+AG18*AH18 -> 0
B19: 0 | C19: =+A19*B19 -> 0 | F19: 0 | G19: =+E19*C19 -> 0 | J19: 0 | K19: =+I19*J19 -> 0 | N19: 0 | O19: =+M19*D19 -> 0 | R19: 0 | S19: =+Q19*R19 -> 0 | V19: 0 | W19: =+U19*V19 -> 0 | Z19: 0 | AA19: =+Y19*Z19 -> 0 | AD19: 0 | AE19: =+AC19*AD19 -> 0 | AH19: 0 | AI19: =+AG19*AH19 -> 0
B20: 0 | C20: =+A20*B20 -> 0 | F20: 0 | G20: =+E20*C20 -> 0 | J20: 0 | K20: =+I20*J20 -> 0 | N20: 0 | O20: =+M20*D20 -> 0 | R20: 0 | S20: =+Q20*R20 -> 0 | V20: 0 | W20: =+U20*V20 -> 0 | Z20: 0 | AA20: =+Y20*Z20 -> 0 | AD20: 0 | AE20: =+AC20*AD20 -> 0 | AH20: 0 | AI20: =+AG20*AH20 -> 0
B21: 0 | C21: =+A21*B21 -> 0 | F21: 0 | G21: =+E21*C21 -> 0 | J21: 0 | K21: =+I21*J21 -> 0 | N21: 0 | O21: =+M21*D21 -> 0 | R21: 0 | S21: =+Q21*R21 -> 0 | V21: 0 | W21: =+U21*V21 -> 0 | Z21: 0 | AA21: =+Y21*Z21 -> 0 | AD21: 0 | AE21: =+AC21*AD21 -> 0 | AH21: 0 | AI21: =+AG21*AH21 -> 0
B22: Total | C22: =SUM(C12:C21) -> 0 | F22: Total | G22: =SUM(G12:G21) -> 0 | J22: Total | K22: =SUM(K12:K21) -> 0 | N22: Total | O22: =SUM(O12:O21) -> 0 | R22: Total | S22: =SUM(S12:S21) -> 0 | V22: Total | W22: =SUM(W12:W21) -> 0 | Z22: Total | AA22: =SUM(AA12:AA21) -> 0 | AD22: Total | AE22: =SUM(AE12:AE21) -> 0 | AH22: Total | AI22: =SUM(AI12:AI21) -> 0
A23: 50/50 Collected | C23: 0 | E23: 50/50 Collected | G23: 0 | I23: 50/50 Collected | K23: 0 | M23: 50/50 Collected | O23: 0 | Q23: 50/50 Collected | S23: 0 | U23: 50/50 Collected | W23: 0 | Y23: 50/50 Collected | AA23: 0 | AC23: 50/50 Collected | AE23: 0 | AG23: 50/50 Collected | AI23: 0
A24: Lideage | C24: =+C32*13.25 -> 0 | E24: Lideage | G24: =+G32*13.25 -> 0 | I24: Lideage | K24: =+K32*13.25 -> 0 | M24: Lideage | O24: =+O32*13.25 -> 0 | Q24: Lideage | S24: =+S32*13.25 -> 0 | U24: Lideage | W24: =+W32*13.25 -> 0 | Y24: Lideage | AA24: =+AA32*13.25 -> 0 | AC24: Lideage | AE24: =+AE32*13.25 -> 0 | AG24: Lideage | AI24: =+AI32*13.25 -> 0
A25: Vegas Rooms | C25: ='1'!G27+'2'!G27+'3'!G27+'4'!G27+'5'!G27+'6'!G27+'7'!G27+'8'!G27+'9'!G27+'10'!G27+'11'!G27+'12'!G27+'13'!G27+'14'!G27+'15'!G27+'16'!G27+'17'!G27+'18'!G27+'19'!G27+'20'!G27 -> 0 | E25: Vegas Rooms | G25: ='1'!G27+'2'!G27+'3'!G27+'4'!G27+'5'!G27+'6'!G27+'7'!G27+'8'!G27+'9'!G27+'10'!G27+'11'!G27+'12'!G27+'13'!G27+'14'!G27+'15'!G27+'16'!G27+'17'!G27+'18'!G27+'19'!G27+'20'!G27 -> 0 | I25: Vegas Rooms | K25: ='1'!G27+'2'!G27+'3'!G27+'4'!G27+'5'!G27+'6'!G27+'7'!G27+'8'!G27+'9'!G27+'10'!G27+'11'!G27+'12'!G27+'13'!G27+'14'!G27+'15'!G27+'16'!G27+'17'!G27+'18'!G27+'19'!G27+'20'!G27 -> 0 | M25: Vegas Rooms | O25: ='1'!G27+'2'!G27+'3'!G27+'4'!G27+'5'!G27+'6'!G27+'7'!G27+'8'!G27+'9'!G27+'10'!G27+'11'!G27+'12'!G27+'13'!G27+'14'!G27+'15'!G27+'16'!G27+'17'!G27+'18'!G27+'19'!G27+'20'!G27 -> 0 | Q25: Vegas Rooms | S25: ='1'!G27+'2'!G27+'3'!G27+'4'!G27+'5'!G27+'6'!G27+'7'!G27+'8'!G27+'9'!G27+'10'!G27+'11'!G27+'12'!G27+'13'!G27+'14'!G27+'15'!G27+'16'!G27+'17'!G27+'18'!G27+'19'!G27+'20'!G27 -> 0 | U25: Vegas Rooms | W25: ='1'!G27+'2'!G27+'3'!G27+'4'!G27+'5'!G27+'6'!G27+'7'!G27+'8'!G27+'9'!G27+'10'!G27+'11'!G27+'12'!G27+'13'!G27+'14'!G27+'15'!G27+'16'!G27+'17'!G27+'18'!G27+'19'!G27+'20'!G27 -> 0 | Y25: Vegas Rooms | AA25: ='1'!G27+'2'!G27+'3'!G27+'4'!G27+'5'!G27+'6'!G27+'7'!G27+'8'!G27+'9'!G27+'10'!G27+'11'!G27+'12'!G27+'13'!G27+'14'!G27+'15'!G27+'16'!G27+'17'!G27+'18'!G27+'19'!G27+'20'!G27 -> 0 | AC25: Vegas Rooms | AE25: ='1'!G27+'2'!G27+'3'!G27+'4'!G27+'5'!G27+'6'!G27+'7'!G27+'8'!G27+'9'!G27+'10'!G27+'11'!G27+'12'!G27+'13'!G27+'14'!G27+'15'!G27+'16'!G27+'17'!G27+'18'!G27+'19'!G27+'20'!G27 -> 0 | AG25: Vegas Rooms | AI25: ='1'!G27+'2'!G27+'3'!G27+'4'!G27+'5'!G27+'6'!G27+'7'!G27+'8'!G27+'9'!G27+'10'!G27+'11'!G27+'12'!G27+'13'!G27+'14'!G27+'15'!G27+'16'!G27+'17'!G27+'18'!G27+'19'!G27+'20'!G27 -> 0
A26: Deposit Total | C26: =+C10+C22+C23+C25 -> 0 | E26: Deposit Total | G26: =+G10+G22+G23+G25 -> 0 | I26: Deposit Total | K26: =+K10+K22+K23+K25 -> 0 | M26: Deposit Total | O26: =+O10+O22+O23+O25 -> 0 | Q26: Deposit Total | S26: =+S10+S22+S23+S25 -> 0 | U26: Deposit Total | W26: =+W10+W22+W23+W25 -> 0 | Y26: Deposit Total | AA26: =+AA10+AA22+AA23+AA25 -> 0 | AC26: Deposit Total | AE26: =+AE10+AE22+AE23+AE25 -> 0 | AG26: Deposit Total | AI26: =+AI10+AI22+AI23+AI25 -> 0
A28: =A1 -> Week 19 | C28: =+'1'!B18+'2'!B18+'3'!B18+'4'!B18+'5'!B18+'6'!B18+'7'!B18+'8'!B18+'9'!B18+'10'!B18+'11'!B18+'12'!B18+'13'!B18+'14'!B18+'15'!B18+'16'!B18+'17'!B18+'18'!B18+'18'!B18+'20'!B18 -> 0 | E28: =E1 -> Week 20 | G28: =+'1'!C18+'2'!C18+'3'!C18+'4'!C18+'5'!C18+'6'!C18+'18'!C18+'8'!C18+'9'!C18+'10'!C18+'11'!C18+'12'!C18+'13'!C18+'14'!C18+'15'!C18+'16'!C18+'18'!C18+'18'!C18+'18'!C18+'18'!C18+'20'!C18 -> 0 | I28: =I1 -> Week 21 | K28: =+'1'!D18+'2'!D18+'3'!D18+'4'!D18+'5'!D18+'6'!D18+'7'!D18+'8'!D18+'9'!D18+'10'!D18+'11'!D18+'12'!D18+'13'!D18+'14'!D18+'15'!D18+'16'!D18+'18'!D18+'18'!D18+'18'!D18+'20'!D18 -> 0 | M28: =M1 -> Week 22 | O28: =+'1'!E18+'2'!E18+'3'!E18+'4'!E18+'5'!E18+'6'!E18+'7'!E18+'8'!E18+'9'!E18+'10'!E18+'11'!E18+'12'!E18+'13'!E18+'14'!E18+'15'!E18+'16'!E18+'18'!E18+'18'!E18+'18'!E18+'20'!E18 -> 0 | Q28: =Q1 -> Week 23 | S28: =+'1'!F18+'2'!F18+'3'!F18+'4'!F18+'5'!F18+'6'!F18+'7'!F18+'8'!F18+'9'!F18+'10'!F18+'11'!F18+'12'!F18+'13'!F18+'14'!F18+'15'!F18+'16'!F18+'18'!F18+'18'!F18+'18'!F18+'20'!F18 -> 0 | U28: =U1 -> Week 24 | W28: =+'1'!G18+'2'!G18+'3'!G18+'4'!G18+'5'!G18+'6'!G18+'7'!G18+'8'!G18+'9'!G18+'10'!G18+'11'!G18+'12'!G18+'13'!G18+'14'!G18+'15'!G18+'16'!G18+'18'!G18+'18'!G18+'18'!G18+'20'!G18 -> 0 | Y28: =Y1 -> Week 25 | AA28: =+'1'!H18+'2'!H18+'3'!H18+'4'!H18+'5'!H18+'6'!H18+'7'!H18+'8'!H18+'9'!H18+'10'!H18+'11'!H18+'12'!H18+'13'!H18+'14'!H18+'15'!H18+'16'!H18+'18'!H18+'18'!H18+'18'!H18+'20'!H18 -> 0 | AC28: =AC1 -> Week 26 | AE28: =+'1'!I18+'2'!I18+'3'!I18+'4'!I18+'5'!I18+'6'!I18+'7'!I18+'8'!I18+'9'!I18+'10'!I18+'11'!I18+'12'!I18+'13'!I18+'14'!I18+'15'!I18+'16'!I18+'18'!I18+'18'!I18+'18'!I18+'20'!I18 -> 0 | AG28: =AG1 -> Week 27 | AI28: =+'1'!J18+'2'!J18+'3'!J18+'4'!J18+'5'!J18+'6'!J18+'7'!J18+'8'!J18+'9'!J18+'10'!J18+'11'!J18+'12'!J18+'13'!J18+'14'!J18+'15'!J18+'16'!J18+'18'!J18+'18'!J18+'18'!J18+'20'!J18 -> 0
A29: DiCC | C29: =+C26-C28 -> 0 | E29: DiCC | G29: =+G26-G28 -> 0 | I29: DiCC | K29: =+K26-K28 -> 0 | M29: DiCC | O29: =+O26-O28 -> 0 | Q29: DiCC | S29: =+S26-S28 -> 0 | U29: DiCC | W29: =+W26-W28 -> 0 | Y29: DiCC | AA29: =+AA26-AA28 -> 0 | AC29: DiCC | AE29: =+AE26-AE28 -> 0 | AG29: DiCC | AI29: =+AI26-AI28 -> 0
A32: # of Bowlers | E32: # of Bowlers | I32: # of Bowlers | M32: # of Bowlers | Q32: # of Bowlers | U32: # of Bowlers | Y32: # of Bowlers | AC32: # of Bowlers | AG32: # of Bowlers

Sheet 4th Qtr
A1: Week 28 | E1: Week 29 | I1: Week 30 | M1: Week 31 | Q1: Week 32 | U1: Week 33 | Y1: Week 34 | AC1: Week 35 | AG1: Week 36
A2: CASH | E2: CASH | I2: CASH | M2: CASH | Q2: CASH | U2: CASH | Y2: CASH | AC2: CASH | AG2: CASH
A3: 1 | B3: 0 | C3: =+A3*B3 -> 0 | E3: 1 | F3: 0 | G3: =+E3*F3 -> 0 | I3: 1 | J3: 0 | K3: =+I3*J3 -> 0 | M3: 1 | N3: 0 | O3: =+M3*N3 -> 0 | Q3: 1 | R3: 0 | S3: =+Q3*R3 -> 0 | U3: 1 | V3: 0 | W3: =+U3*V3 -> 0 | Y3: 1 | Z3: 0 | AA3: =+Y3*Z3 -> 0 | AC3: 1 | AD3: 0 | AE3: =+AC3*AD3 -> 0 | AG3: 1 | AH3: 0 | AI3: =+AG3*AH3 -> 0
A4: 5 | B4: 0 | C4: =+A4*B4 -> 0 | E4: 5 | F4: 0 | G4: =+E4*F4 -> 0 | I4: 5 | J4: 0 | K4: =+I4*J4 -> 0 | M4: 5 | N4: 0 | O4: =+M4*N4 -> 0 | Q4: 5 | R4: 0 | S4: =+Q4*R4 -> 0 | U4: 5 | V4: 0 | W4: =+U4*V4 -> 0 | Y4: 5 | Z4: 0 | AA4: =+Y4*Z4 -> 0 | AC4: 5 | AD4: 0 | AE4: =+AC4*AD4 -> 0 | AG4: 5 | AH4: 0 | AI4: =+AG4*AH4 -> 0
A5: 10 | B5: 0 | C5: =+A5*B5 -> 0 | E5: 10 | F5: 0 | G5: =+E5*F5 -> 0 | I5: 10 | J5: 0 | K5: =+I5*J5 -> 0 | M5: 10 | N5: 0 | O5: =+M5*N5 -> 0 | Q5: 10 | R5: 0 | S5: =+Q5*R5 -> 0 | U5: 10 | V5: 0 | W5: =+U5*V5 -> 0 | Y5: 10 | Z5: 0 | AA5: =+Y5*Z5 -> 0 | AC5: 10 | AD5: 0 | AE5: =+AC5*AD5 -> 0 | AG5: 10 | AH5: 0 | AI5: =+AG5*AH5 -> 0
A6: 20 | B6: 0 | C6: =+A6*B6 -> 0 | E6: 20 | F6: 0 | G6: =+E6*F6 -> 0 | I6: 20 | J6: 0 | K6: =+I6*J6 -> 0 | M6: 20 | N6: 0 | O6: =+M6*N6 -> 0 | Q6: 20 | R6: 0 | S6: =+Q6*R6 -> 0 | U6: 20 | V6: 0 | W6: =+U6*V6 -> 0 | Y6: 20 | Z6: 0 | AA6: =+Y6*Z6 -> 0 | AC6: 20 | AD6: 0 | AE6: =+AC6*AD6 -> 0 | AG6: 20 | AH6: 0 | AI6: =+AG6*AH6 -> 0
A7: 20 | B7: 0 | C7: =+A7*B7 -> 0 | E7: 20 | F7: 0 | G7: =+E7*F7 -> 0 | I7: 20 | J7: 0 | K7: =+I7*J7 -> 0 | M7: 20 | N7: 0 | O7: =+M7*N7 -> 0 | Q7: 20 | R7: 0 | S7: =+Q7*R7 -> 0 | U7: 20 | V7: 0 | W7: =+U7*V7 -> 0 | Y7: 20 | Z7: 0 | AA7: =+Y7*Z7 -> 0 | AC7: 20 | AD7: 0 | AE7: =+AC7*AD7 -> 0 | AG7: 20 | AH7: 0 | AI7: =+AG7*AH7 -> 0
A8: 50 | B8: 0 | C8: =+A8*B8 -> 0 | E8: 50 | F8: 0 | G8: =+E8*F8 -> 0 | I8: 50 | J8: 0 | K8: =+I8*J8 -> 0 | M8: 50 | N8: 0 | O8: =+M8*N8 -> 0 | Q8: 50 | R8: 0 | S8: =+Q8*R8 -> 0 | U8: 50 | V8: 0 | W8: =+U8*V8 -> 0 | Y8: 50 | Z8: 0 | AA8: =+Y8*Z8 -> 0 | AC8: 50 | AD8: 0 | AE8: =+AC8*AD8 -> 0 | AG8: 50 | AH8: 0 | AI8: =+AG8*AH8 -> 0
A9: 100 | B9: 0 | C9: =+A9*B9 -> 0 | E9: 100 | F9: 0 | G9: =+E9*F9 -> 0 | I9: 100 | J9: 0 | K9: =+I9*J9 -> 0 | M9: 100 | N9: 0 | O9: =+M9*N9 -> 0 | Q9: 100 | R9: 0 | S9: =+Q9*R9 -> 0 | U9: 100 | V9: 0 | W9: =+U9*V9 -> 0 | Y9: 100 | Z9: 0 | AA9: =+Y9*Z9 -> 0 | AC9: 100 | AD9: 0 | AE9: =+AC9*AD9 -> 0 | AG9: 100 | AH9: 0 | AI9: =+AG9*AH9 -> 0
B10: Total | C10: =SUM(C3:C9) -> 0 | F10: Total | G10: =SUM(G3:G9) -> 0 | J10: Total | K10: =SUM(K3:K9) -> 0 | N10: Total | O10: =SUM(O3:O9) -> 0 | R10: Total | S10: =SUM(S3:S9) -> 0 | V10: Total | W10: =SUM(W3:W9) -> 0 | Z10: Total | AA10: =SUM(AA3:AA9) -> 0 | AD10: Total | AE10: =SUM(AE3:AE9) -> 0 | AH10: Total | AI10: =SUM(AI3:AI9) -> 0
A11: Checks | E11: Checks | I11: Checks | M11: Checks | Q11: Checks | U11: Checks | Y11: Checks | AC11: Checks | AG11: Checks
A12: 30 | B12: 0 | C12: =+A12*B12 -> 0 | E12: 30 | F12: 0 | G12: =+E12*F12 -> 0 | I12: 30 | J12: 0 | K12: =+I12*J12 -> 0 | M12: 30 | N12: 0 | O12: =+M12*N12 -> 0 | Q12: 30 | R12: 0 | S12: =+Q12*R12 -> 0 | U12: 30 | V12: 0 | W12: =+U12*V12 -> 0 | Y12: 30 | Z12: 0 | AA12: =+Y12*Z12 -> 0 | AC12: 30 | AD12: 0 | AE12: =+AC12*AD12 -> 0 | AG12: 30 | AH12: 0 | AI12: =+AG12*AH12 -> 0
A13: 60 | B13: 0 | C13: =+A13*B13 -> 0 | E13: 60 | F13: 0 | G13: =+E13*F13 -> 0 | I13: 60 | J13: 0 | K13: =+I13*J13 -> 0 | M13: 60 | N13: 0 | O13: =+M13*N13 -> 0 | Q13: 60 | R13: 0 | S13: =+Q13*R13 -> 0 | U13: 60 | V13: 0 | W13: =+U13*V13 -> 0 | Y13: 60 | Z13: 0 | AA13: =+Y13*Z13 -> 0 | AC13: 60 | AD13: 0 | AE13: =+AC13*AD13 -> 0 | AG13: 60 | AH13: 0 | AI13: =+AG13*AH13 -> 0
A14: 90 | B14: 0 | C14: =+A14*B14 -> 0 | E14: 90 | F14: 0 | G14: =+E14*F14 -> 0 | I14: 90 | J14: 0 | K14: =+I14*J14 -> 0 | M14: 90 | N14: 0 | O14: =+M14*N14 -> 0 | Q14: 90 | R14: 0 | S14: =+Q14*R14 -> 0 | U14: 90 | V14: 0 | W14: =+U14*V14 -> 0 | Y14: 90 | Z14: 0 | AA14: =+Y14*Z14 -> 0 | AC14: 90 | AD14: 0 | AE14: =+AC14*AD14 -> 0 | AG14: 90 | AH14: 0 | AI14: =+AG14*AH14 -> 0
A15: 120 | B15: 0 | C15: =+A15*B15 -> 0 | E15: 120 | F15: 0 | G15: =+E15*F15 -> 0 | I15: 120 | J15: 0 | K15: =+I15*J15 -> 0 | M15: 120 | N15: 0 | O15: =+M15*N15 -> 0 | Q15: 120 | R15: 0 | S15: =+Q15*R15 -> 0 | U15: 120 | V15: 0 | W15: =+U15*V15 -> 0 | Y15: 120 | Z15: 0 | AA15: =+Y15*Z15 -> 0 | AC15: 120 | AD15: 0 | AE15: =+AC15*AD15 -> 0 | AG15: 120 | AH15: 0 | AI15: =+AG15*AH15 -> 0
B16: 0 | C16: =+A16*B16 -> 0 | F16: 0 | G16: =+E16*F16 -> 0 | J16: 0 | K16: =+I16*J16 -> 0 | N16: 0 | O16: =+M16*N16 -> 0 | R16: 0 | S16: =+Q16*R16 -> 0 | V16: 0 | W16: =+U16*V16 -> 0 | Z16: 0 | AA16: =+Y16*Z16 -> 0 | AD16: 0 | AE16: =+AC16*AD16 -> 0 | AH16: 0 | AI16: =+AG16*AH16 -> 0
B17: 0 | C17: =+A17*B17 -> 0 | F17: 0 | G17: =+E17*F17 -> 0 | J17: 0 | K17: =+I17*J17 -> 0 | N17: 0 | O17: =+M17*N17 -> 0 | R17: 0 | S17: =+Q17*R17 -> 0 | V17: 0 | W17: =+U17*V17 -> 0 | Z17: 0 | AA17: =+Y17*Z17 -> 0 | AD17: 0 | AE17: =+AC17*AD17 -> 0 | AH17: 0 | AI17: =+AG17*AH17 -> 0
B18: 0 | C18: =+A18*B18 -> 0 | F18: 0 | G18: =+E18*F18 -> 0 | J18: 0 | K18: =+I18*J18 -> 0 | N18: 0 | O18: =+M18*N18 -> 0 | R18: 0 | S18: =+Q18*R18 -> 0 | V18: 0 | W18: =+U18*V18 -> 0 | Z18: 0 | AA18: =+Y18*Z18 -> 0 | AD18: 0 | AE18: =+AC18*AD18 -> 0 | AH18: 0 | AI18: =+AG18*AH18 -> 0
B19: 0 | C19: =+A19*B19 -> 0 | F19: 0 | G19: =+E19*F19 -> 0 | J19: 0 | K19: =+I19*J19 -> 0 | N19: 0 | O19: =+M19*N19 -> 0 | R19: 0 | S19: =+Q19*R19 -> 0 | V19: 0 | W19: =+U19*V19 -> 0 | Z19: 0 | AA19: =+Y19*Z19 -> 0 | AD19: 0 | AE19: =+AC19*AD19 -> 0 | AH19: 0 | AI19: =+AG19*AH19 -> 0
B20: 0 | C20: =+A20*B20 -> 0 | F20: 0 | G20: =+E20*F20 -> 0 | J20: 0 | K20: =+I20*J20 -> 0 | N20: 0 | O20: =+M20*N20 -> 0 | R20: 0 | S20: =+Q20*R20 -> 0 | V20: 0 | W20: =+U20*V20 -> 0 | Z20: 0 | AA20: =+Y20*Z20 -> 0 | AD20: 0 | AE20: =+AC20*AD20 -> 0 | AH20: 0 | AI20: =+AG20*AH20 -> 0
B21: 0 | C21: =+A21*B21 -> 0 | F21: 0 | G21: =+E21*F21 -> 0 | J21: 0 | K21: =+I21*J21 -> 0 | N21: 0 | O21: =+M21*N21 -> 0 | R21: 0 | S21: =+Q21*R21 -> 0 | V21: 0 | W21: =+U21*V21 -> 0 | Z21: 0 | AA21: =+Y21*Z21 -> 0 | AD21: 0 | AE21: =+AC21*AD21 -> 0 | AH21: 0 | AI21: =+AG21*AH21 -> 0
B22: Total | C22: =SUM(C12:C21) -> 0 | F22: Total | G22: =SUM(G12:G21) -> 0 | J22: Total | K22: =SUM(K12:K21) -> 0 | N22: Total | O22: =SUM(O12:O21) -> 0 | R22: Total | S22: =SUM(S12:S21) -> 0 | V22: Total | W22: =SUM(W12:W21) -> 0 | Z22: Total | AA22: =SUM(AA12:AA21) -> 0 | AD22: Total | AE22: =SUM(AE12:AE21) -> 0 | AH22: Total | AI22: =SUM(AI12:AI21) -> 0
A23: 50/50 Collected | C23: 0 | E23: 50/50 Collected | G23: 0 | I23: 50/50 Collected | K23: 0 | M23: 50/50 Collected | O23: 0 | Q23: 50/50 Collected | S23: 0 | U23: 50/50 Collected | W23: 0 | Y23: 50/50 Collected | AA23: 0 | AC23: 50/50 Collected | AE23: 0 | AG23: 50/50 Collected | AI23: 0
A24: Lineage | C24: =+C32*13.25 -> 0 | E24: Lineage | G24: =+G32*13.25 -> 0 | I24: Lineage | K24: =+K32*13.25 -> 0 | M24: Lineage | O24: =+O32*13.25 -> 0 | Q24: Lineage | S24: =+S32*13.25 -> 0 | U24: Lineage | W24: =+W32*13.25 -> 0 | Y24: Lineage | AA24: =+AA32*13.25 -> 0 | AC24: Lineage | AE24: =+AE32*13.25 -> 0 | AG24: Lineage | AI24: =+AI32*13.25 -> 0
A25: Vegas Rooms | C25: ='1'!G27+'2'!G27+'3'!G27+'4'!G27+'5'!G27+'6'!G27+'7'!G27+'8'!G27+'9'!G27+'10'!G27+'11'!G27+'12'!G27+'13'!G27+'14'!G27+'15'!G27+'16'!G27+'17'!G27+'18'!G27+'19'!G27+'20'!G27 -> 0 | E25: Vegas Rooms | G25: ='1'!G27+'2'!G27+'3'!G27+'4'!G27+'5'!G27+'6'!G27+'7'!G27+'8'!G27+'9'!G27+'10'!G27+'11'!G27+'12'!G27+'13'!G27+'14'!G27+'15'!G27+'16'!G27+'17'!G27+'18'!G27+'19'!G27+'20'!G27 -> 0 | I25: Vegas Rooms | K25: ='1'!G27+'2'!G27+'3'!G27+'4'!G27+'5'!G27+'6'!G27+'7'!G27+'8'!G27+'9'!G27+'10'!G27+'11'!G27+'12'!G27+'13'!G27+'14'!G27+'15'!G27+'16'!G27+'17'!G27+'18'!G27+'19'!G27+'20'!G27 -> 0 | M25: Vegas Rooms | O25: ='1'!G27+'2'!G27+'3'!G27+'4'!G27+'5'!G27+'6'!G27+'7'!G27+'8'!G27+'9'!G27+'10'!G27+'11'!G27+'12'!G27+'13'!G27+'14'!G27+'15'!G27+'16'!G27+'17'!G27+'18'!G27+'19'!G27+'20'!G27 -> 0 | Q25: Vegas Rooms | S25: ='1'!G27+'2'!G27+'3'!G27+'4'!G27+'5'!G27+'6'!G27+'7'!G27+'8'!G27+'9'!G27+'10'!G27+'11'!G27+'12'!G27+'13'!G27+'14'!G27+'15'!G27+'16'!G27+'17'!G27+'18'!G27+'19'!G27+'20'!G27 -> 0 | U25: Vegas Rooms | W25: ='1'!G27+'2'!G27+'3'!G27+'4'!G27+'5'!G27+'6'!G27+'7'!G27+'8'!G27+'9'!G27+'10'!G27+'11'!G27+'12'!G27+'13'!G27+'14'!G27+'15'!G27+'16'!G27+'17'!G27+'18'!G27+'19'!G27+'20'!G27 -> 0 | Y25: Vegas Rooms | AA25: ='1'!G27+'2'!G27+'3'!G27+'4'!G27+'5'!G27+'6'!G27+'7'!G27+'8'!G27+'9'!G27+'10'!G27+'11'!G27+'12'!G27+'13'!G27+'14'!G27+'15'!G27+'16'!G27+'17'!G27+'18'!G27+'19'!G27+'20'!G27 -> 0 | AC25: Vegas Rooms | AE25: ='1'!G27+'2'!G27+'3'!G27+'4'!G27+'5'!G27+'6'!G27+'7'!G27+'8'!G27+'9'!G27+'10'!G27+'11'!G27+'12'!G27+'13'!G27+'14'!G27+'15'!G27+'16'!G27+'17'!G27+'18'!G27+'19'!G27+'20'!G27 -> 0 | AG25: Vegas Rooms | AI25: ='1'!G27+'2'!G27+'3'!G27+'4'!G27+'5'!G27+'6'!G27+'7'!G27+'8'!G27+'9'!G27+'10'!G27+'11'!G27+'12'!G27+'13'!G27+'14'!G27+'15'!G27+'16'!G27+'17'!G27+'18'!G27+'19'!G27+'20'!G27 -> 0
A26: Deposit Total | C26: =+C10+C22+C23+C25 -> 0 | E26: Deposit Total | G26: =+G10+G22+G23+G25 -> 0 | I26: Deposit Total | K26: =+K10+K22+K23+K25 -> 0 | M26: Deposit Total | O26: =+O10+O22+O23+O25 -> 0 | Q26: Deposit Total | S26: =+S10+S22+S23+S25 -> 0 | U26: Deposit Total | W26: =+W10+W22+W23+W25 -> 0 | Y26: Deposit Total | AA26: =+AA10+AA22+AA23+AA25 -> 0 | AC26: Deposit Total | AE26: =+AE10+AE22+AE23+AE25 -> 0 | AG26: Deposit Total | AI26: =+AI10+AI22+AI23+AI25 -> 0
A28: =A1 -> Week 28 | C28: =+'1'!K18+'2'!K18+'3'!K18+'4'!K18+'5'!K18+'6'!K18+'7'!K18+'8'!K18+'9'!K18+'10'!K18+'11'!K18+'12'!K18+'13'!K18+'14'!K18+'15'!K18+'16'!K18+'18'!K18+'18'!K18+'18'!K18+'20'!K18 -> 0 | E28: =E1 -> Week 29 | G28: =+'1'!L18+'2'!L18+'3'!L18+'4'!L18+'5'!L18+'6'!L18+'7'!L18+'8'!L18+'9'!L18+'10'!L18+'11'!L18+'12'!L18+'13'!L18+'14'!L18+'15'!L18+'16'!L18+'18'!L18+'18'!L18+'18'!L18+'20'!L18 -> 0 | I28: =I1 -> Week 30 | K28: =+'1'!M18+'2'!M18+'3'!M18+'4'!M18+'5'!M18+'6'!M18+'7'!M18+'8'!M18+'9'!M18+'10'!M18+'11'!M18+'12'!M18+'13'!M18+'14'!M18+'15'!M18+'16'!M18+'18'!M18+'18'!M18+'18'!M18+'20'!M18 -> 0 | M28: =M1 -> Week 31 | O28: =+'1'!N18+'2'!N18+'3'!N18+'4'!N18+'5'!N18+'6'!N18+'7'!N18+'8'!N18+'9'!N18+'10'!N18+'11'!N18+'12'!N18+'13'!N18+'14'!N18+'15'!N18+'16'!N18+'18'!N18+'18'!N18+'18'!N18+'20'!N18 -> 0 | Q28: =Q1 -> Week 32 | S28: =+'1'!O18+'2'!O18+'3'!O18+'4'!O18+'5'!O18+'6'!O18+'7'!O18+'8'!O18+'9'!O18+'10'!O18+'11'!O18+'12'!O18+'13'!O18+'14'!O18+'15'!O18+'16'!O18+'18'!O18+'18'!O18+'18'!O18+'20'!O18 -> 0 | U28: =U1 -> Week 33 | W28: =+'1'!P18+'2'!P18+'3'!P18+'4'!P18+'5'!P18+'6'!P18+'7'!P18+'8'!P18+'9'!P18+'10'!P18+'11'!P18+'12'!P18+'13'!P18+'14'!P18+'15'!P18+'16'!P18+'18'!P18+'18'!P18+'18'!P18+'20'!P18 -> 0 | Y28: =Y1 -> Week 34 | AA28: =+'1'!Q18+'2'!Q18+'3'!Q18+'4'!Q18+'5'!Q18+'6'!Q18+'7'!Q18+'8'!Q18+'9'!Q18+'10'!Q18+'11'!Q18+'12'!Q18+'13'!Q18+'14'!Q18+'15'!Q18+'16'!Q18+'18'!Q18+'18'!Q18+'18'!Q18+'20'!Q18 -> 0 | AC28: =AC1 -> Week 35 | AE28: =+'1'!R18+'2'!R18+'3'!R18+'4'!R18+'5'!R18+'6'!R18+'7'!R18+'8'!R18+'9'!R18+'10'!R18+'11'!R18+'12'!R18+'13'!R18+'14'!R18+'15'!R18+'16'!R18+'18'!R18+'18'!R18+'18'!R18+'20'!R18 -> 0 | AG28: =AG1 -> Week 36 | AI28: =+'1'!S18+'2'!S18+'3'!S18+'4'!S18+'5'!S18+'6'!S18+'7'!S18+'8'!S18+'9'!S18+'10'!S18+'11'!S18+'12'!S18+'13'!S18+'14'!S18+'15'!S18+'16'!S18+'18'!S18+'18'!S18+'18'!S18+'20'!S18 -> 0
A29: Diff | C29: =+C26-C28 -> 0 | E29: Diff | G29: =+G26-G28 -> 0 | I29: Diff | K29: =+K26-K28 -> 0 | M29: Diff | O29: =+O26-O28 -> 0 | Q29: Diff | S29: =+S26-S28 -> 0 | U29: Diff | W29: =+W26-W28 -> 0 | Y29: Diff | AA29: =+AA26-AA28 -> 0 | AC29: Diff | AE29: =+AE26-AE28 -> 0 | AG29: Diff | AI29: =+AI26-AI28 -> 0
A32: # of Bowlers | E32: # of Bowlers | I32: # of Bowlers | M32: # of Bowlers | Q32: # of Bowlers | U32: # of Bowlers | Y32: # of Bowlers | AC32: # of Bowlers | AG32: # of Bowlers

Sheet Summary
B2: Quarter 1 | H2: Quarter 3
B3: Week # | C3: Debit | D3: Credit | E3: Total | F3: Notes | H3: Week # | I3: Debit | J3: Credit | K3: Total | L3: Notes
B4: 1 | D4: 3397.75 | E4: =C4+D4 -> 3397.75 | F4: FIRST WEEK MINUS THE LINEAGE | H4: =B26+1 -> 19 | K4: =I4+J4 -> 0
B5: 2 | C5: -1060 | D5: 1977 | E5: =C5+D5 -> 917 | F5: 2 $30 checks were not deposited | H5: =H4+1 -> 20 | K5: =I5+J5 -> 0
B6: 3 | C6: =-1139.5-42 -> -1181.5 | D6: 2427.5 | E6: =C6+D6 -> 1246 | F6: Debits 1139.50linage & 42 for bls 60 from week 2 deposited. | H6: =H5+1 -> 21 | K6: =I6+J6 -> 0
B7: 4 | C7: -1192.5 | D7: 4486.25 | E7: =C7+D7 -> 3293.75 | F7: Debits 1192.50 | H7: =H6+1 -> 22 | K7: =I7+J7 -> 0
B8: 5 | C8: -1192.5 | D8: 3692.75 | E8: =C8+D8 -> 2500.25 | F8: Debits 1192.50 | H8: =H7+1 -> 23 | K8: =I8+J8 -> 0
B9: 6 | C9: -1113 | D9: 3198.25 | E9: =C9+D9 -> 2085.25 | F9: Debits 1113.00 | H9: =H8+1 -> 24 | K9: =I9+J9 -> 0
B10: 7 | C10: -1113 | D10: 1935.7 | E10: =C10+D10 -> 822.7 | F10: crafts 37.50 Debits 1113.00 Service charge 16.80 | H10: =H9+1 -> 25 | K10: =I10+J10 -> 0
B11: 8 | C11: -1046.75 | D11: 3208 | E11: =C11+D11 -> 2161.25 | F11: debits 1046.75 zelle -200 sec fee | H11: =H10+1 -> 26 | K11: =I11+J11 -> 0
B12: 9 | C12: 1033.5 | D12: 1927.5 | E12: =C12+D12 -> 2961 | F12: debits 1033.50 Zelles 60 100 120 | H12: =H11+1 -> 27 | K12: =I12+J12 -> 0
B14: Total | C14: =SUM(C4:C12) -> -6865.75 | D14: =SUM(D4:D12) -> 26250.7 | E14: =C14+D14 -> 19384.95 | H14: Total | I14: =SUM(I4:I12) -> 0 | J14: =SUM(J4:J12) -> 0 | K14: =I14+J14 -> 0
B16: Quarter 2 | H16: Quarter 4
B17: Week # | C17: Debit | D17: Credit | E17: Total | F17: Notes | H17: Week # | I17: Debit | J17: Credit | K17: Total | L17: Notes
B18: =B12+1 -> 10 | E18: =C18+D18 -> 0 | F18: 50 sec fee | H18: =H12+1 -> 28 | K18: =I18+J18 -> 0
B19: =B18+1 -> 11 | E19: =C19+D19 -> 0 | F19: crafts20+52 | H19: =H18+1 -> 29 | K19: =I19+J19 -> 0
B20: =B19+1 -> 12 | E20: =C20+D20 -> 0 | F20: 220 sec fee | H20: =H19+1 -> 30 | K20: =I20+J20 -> 0
B21: =B20+1 -> 13 | E21: =C21+D21 -> 0 | H21: =H20+1 -> 31 | K21: =I21+J21 -> 0
B22: =B21+1 -> 14 | E22: =C22+D22 -> 0 | H22: =H21+1 -> 32 | K22: =I22+J22 -> 0
B23: =B22+1 -> 15 | E23: =C23+D23 -> 0 | H23: =H22+1 -> 33 | K23: =I23+J23 -> 0
B24: =B23+1 -> 16 | E24: =C24+D24 -> 0 | H24: =H23+1 -> 34 | K24: =I24+J24 -> 0
B25: =B24+1 -> 17 | E25: =C25+D25 -> 0 | H25: =H24+1 -> 35 | K25: =I25+J25 -> 0
B26: =B25+1 -> 18 | E26: =C26+D26 -> 0 | H26: =H25+1 -> 36 | K26: =I26+J26 -> 0
B28: Total | C28: =SUM(C18:C26) -> 0 | D28: =SUM(D18:D26) -> 0 | E28: =C28+D28 -> 0 | H28: Total | I28: =SUM(I18:I26) -> 0 | J28: =SUM(J18:J26) -> 0 | K28: =I28+J28 -> 0

Sheet 1
A1: Bowler | B1: 1 | C1: 2 | D1: 3 | E1: 4 | F1: 5 | G1: 6 | H1: 7 | I1: 8 | J1: 9 | K1: 10 | L1: 11 | M1: 12 | N1: 13 | O1: 14 | P1: 15 | Q1: 16 | R1: 17 | S1: 18
A2: Shawn Lemons | B2: 30 | D2: 100 | F2: 60 | J2: 30 | K2: 30 | S2: 60 | T2: =SUM(B2:S2) -> 310
A3: Glenna Morris | B3: 0 | T3: =SUM(B3:S3) -> 0
A4: Phil Stancato | B4: 30 | C4: 40 | D4: 90 | E4: 30 | F4: 30 | G4: 30 | I4: 60 | N4: 60 | O4: 60 | P4: 60 | R4: 30 | S4: 60 | T4: =SUM(B4:S4) -> 580
A5: Ben Bowman | B5: 30 | D5: 60 | E5: 30 | F5: 60 | G5: 60 | J5: 100 | N5: 60 | O5: 100 | Q5: 60 | T5: =SUM(B5:S5) -> 560
A6: Jeff Goudie | B6: 0 | C6: 120 | F6: 180 | L6: 90 | P6: 90 | T6: =SUM(B6:S6) -> 480
T7: =SUM(B7:S7) -> 0
A8: Sub | C8: 5 | M8: 5 | Q8: 5 | T8: =SUM(B8:S8) -> 15
B9: =SUM(B2:B8) -> 90 | C9: =SUM(C2:C8) -> 165 | D9: =SUM(D2:D8) -> 250 | E9: =SUM(E2:E8) -> 60 | F9: =SUM(F2:F8) -> 330 | G9: =SUM(G2:G8) -> 90 | H9: =SUM(H2:H8) -> 0 | I9: =SUM(I2:I8) -> 60 | ... T9: =SUM(T2:T8) -> 1945
A10: Bowler | B10: 19 | C10: 20 | D10: 21 | E10: 22 | F10: 23 | G10: 24 | H10: 25 | I10: 26 | J10: 27 | K10: 28 | L10: 29 | M10: 30 | N10: 31 | O10: 32 | P10: 33 | Q10: 34 | R10: 35 | S10: 36
A11: Shawn Lemons | T11: =SUM(B11:S11) -> 0
A12: Glenna Morris | T12: =SUM(B12:S12) -> 0
A13: Phil Stancato | T13: =SUM(B13:S13) -> 0
A14: Ben Bowman | T14: =SUM(B14:S14) -> 0
A15: Jeff Goudie | T15: =SUM(B15:S15) -> 0
T16: =SUM(B16:S16) -> 0
A17: Sub | T17: =SUM(B17:S17) -> 0
B18: =SUM(B11:B17) -> 0 | C18: =SUM(C11:C17) -> 0 | D18: =SUM(D11:D17) -> 0 | E18: =SUM(E11:E17) -> 0 | F18: =SUM(F11:F17) -> 0 | G18: =SUM(G11:G17) -> 0 | H18: =SUM(H11:H17) -> 0 | I18: =SUM(I11:I17) -> 0 | ... T18: =SUM(T11:T17) -> 0
A20: Bowler | B20: 25/26 Season | C20: Paid | D20: Balance | F20: Rooms | G20: Paid | H20: Balance
A21: Shawn Lemons | B21: =(36*30)+10 -> 1090 | C21: =+T2+T11 -> 310 | D21: =+B21-C21 -> 780 | F21: 0 | G21: 0 | H21: =+F21-G21 -> 0
A22: Glenna Morris | B22: =(36*30)+10-477 -> 613 | C22: =+T3+T12 -> 0 | D22: =+B22-C22 -> 613 | F22: 0 | G22: 0 | H22: =+F22-G22 -> 0
A23: Phil Stancato | B23: =(36*30)+10 -> 1090 | C23: =+T4+T13 -> 580 | D23: =+B23-C23 -> 510 | F23: 0 | G23: 0 | H23: =+F23-G23 -> 0
A24: Ben Bowman | B24: =(36*30)+10 -> 1090 | C24: =+T5+T14 -> 560 | D24: =+B24-C24 -> 530 | F24: 0 | G24: 0 | H24: =+F24-G24 -> 0
A25: Jeff Goudie | B25: =(36*30)+10 -> 1090 | C25: =+T6+T15 -> 480 | D25: =+B25-C25 -> 610 | F25: 0 | G25: 0 | H25: =+F25-G25 -> 0
C26: =+T8+T17 -> 15 | D26: =+B26-C26 -> -15 | F26: 0 | G26: 0 | H26: =+F26-G26 -> 0
F27: Total | G27: =SUM(G21:G26) -> 0

Sheet 2
A1: Bowler | B1: 1 | C1: 2 | D1: 3 | E1: 4 | F1: 5 | G1: 6 | H1: 7 | I1: 8 | J1: 9 | K1: 10 | L1: 11 | M1: 12 | N1: 13 | O1: 14 | P1: 15 | Q1: 16 | R1: 17 | S1: 18
A2: Tina Markel | B2: 240 | J2: 120 | N2: 120 | Q2: 120 | T2: =SUM(B2:S2) -> 600
A3: Robert Shields | B3: 60 | D3: 300 | L3: 150 | P3: 120 | T3: =SUM(B3:S3) -> 630
A4: Danny Brewer | B4: 30 | D4: 60 | E4: 30 | G4: 60 | I4: 100 | J4: 20 | K4: 30 | L4: 30 | O4: 90 | Q4: 90 | S4: 60 | T4: =SUM(B4:S4) -> 600
A5: Nick Brewer | B5: 30 | C5: 30 | D5: 30 | E5: 30 | F5: 30 | G5: 30 | H5: 60 | J5: 120 | L5: 60 | N5: 60 | R5: 60 | T5: =SUM(B5:S5) -> 540
A6: Kyle Brookshire | B6: 70 | T6: =SUM(B6:S6) -> 70
A7: 6 | T7: =SUM(B7:S7) -> 0
A8: Sub | T8: =SUM(B8:S8) -> 0
B9: =SUM(B2:B8) -> 430 | C9: =SUM(C2:C8) -> 30 | D9: =SUM(D2:D8) -> 390 | E9: =SUM(E2:E8) -> 60 | F9: =SUM(F2:F8) -> 30 | G9: =SUM(G2:G8) -> 90 | H9: =SUM(H2:H8) -> 60 | I9: =SUM(I2:I8) -> 100 | ... T9: =SUM(T2:T8) -> 2440
A10: Bowler | B10: 19 | C10: 20 | D10: 21 | E10: 22 | F10: 23 | G10: 24 | H10: 25 | I10: 26 | J10: 27 | K10: 28 | L10: 29 | M10: 30 | N10: 31 | O10: 32 | P10: 33 | Q10: 34 | R10: 35 | S10: 36
A11: 1 | T11: =SUM(B11:S11) -> 0
A12: 2 | T12: =SUM(B12:S12) -> 0
A13: 3 | T13: =SUM(B13:S13) -> 0
A14: 4 | T14: =SUM(B14:S14) -> 0
A15: 5 | T15: =SUM(B15:S15) -> 0
A16: 6 | T16: =SUM(B16:S16) -> 0
A17: Sub
B18: =SUM(B11:B17) -> 0 | C18: =SUM(C11:C17) -> 0 | D18: =SUM(D11:D17) -> 0 | E18: =SUM(E11:E17) -> 0 | F18: =SUM(F11:F17) -> 0 | G18: =SUM(G11:G17) -> 0 | H18: =SUM(H11:H17) -> 0 | I18: =SUM(I11:I17) -> 0 | ... T18: =SUM(T11:T17) -> 0
A20: Bowler | B20: 25/26 Season | C20: Paid | D20: Balance | F20: Rooms | G20: Paid | H20: Balance
A21: Tina Markel | B21: =(36*30)+10 -> 1090 | C21: =+T2+T11 -> 600 | D21: =+B21-C21 -> 490 | F21: 0 | G21: 0 | H21: =+F21-G21 -> 0
A22: Robert Shields | B22: =(36*30)+10 -> 1090 | C22: =+T3+T12 -> 630 | D22: =+B22-C22 -> 460 | F22: 0 | G22: 0 | H22: =+F22-G22 -> 0
A23: Danny Brewer | B23: =(36*30)+10 -> 1090 | C23: =+T4+T13 -> 600 | D23: =+B23-C23 -> 490 | F23: 0 | G23: 0 | H23: =+F23-G23 -> 0
A24: Nick Brewer | B24: =(36*30)+10 -> 1090 | C24: =+T5+T14 -> 540 | D24: =+B24-C24 -> 550 | F24: 0 | G24: 0 | H24: =+F24-G24 -> 0
A25: Kyle Brookshire | B25: =(36*30)+10 -> 1090 | C25: =+T6+T15 -> 70 | D25: =+B25-C25 -> 1020 | F25: 0 | G25: 0 | H25: =+F25-G25 -> 0
A26: 6 | B26: =(36*30)+10 -> 1090 | C26: =+T8+T18 -> 0 | D26: =+B26-C26 -> 1090 | F26: 0 | G26: 0 | H26: =+F26-G26 -> 0
F27: Total | G27: =SUM(G21:G26) -> 0

Sheet 3
A1: Bowler | B1: 1 | C1: 2 | D1: 3 | E1: 4 | F1: 5 | G1: 6 | H1: 7 | I1: 8 | J1: 9 | K1: 10 | L1: 11 | M1: 12 | N1: 13 | O1: 14 | P1: 15 | Q1: 16 | R1: 17 | S1: 18
A2: Hillary Chambers | E2: 1090 | T2: =SUM(B2:S2) -> 1090
A3: Holly Danielsen | B3: 400 | I3: 100 | K3: 100 | N3: 30 | O3: 30 | P3: 60 | Q3: 30 | R3: 30 | S3: 30 | T3: =SUM(B3:S3) -> 810
A4: Alexandra Yorgensen | B4: 30 | C4: 30 | D4: 30 | E4: 30 | F4: 30 | H4: 40 | K4: 120 | N4: 60 | O4: 30 | P4: 30 | Q4: 30 | R4: 30 | S4: 30 | T4: =SUM(B4:S4) -> 520
A5: Christopher Yazzie | B5: 60 | E5: 60 | G5: 120 | I5: 60 | L5: 100 | N5: 60 | O5: 60 | Q5: 60 | S5: 60 | T5: =SUM(B5:S5) -> 640
A6: 5 | L6: 60 | T6: =SUM(B6:S6) -> 60
A7: 6 | T7: =SUM(B7:S7) -> 0
A8: Sub | T8: =SUM(B8:S8) -> 0
B9: =SUM(B2:B8) -> 490 | C9: =SUM(C2:C8) -> 30 | D9: =SUM(D2:D8) -> 30 | E9: =SUM(E2:E8) -> 1180 | F9: =SUM(F2:F8) -> 30 | G9: =SUM(G2:G8) -> 120 | H9: =SUM(H2:H8) -> 40 | I9: =SUM(I2:I8) -> 160 | ... T9: =SUM(T2:T8) -> 3120
A10: Bowler | B10: 19 | C10: 20 | D10: 21 | E10: 22 | F10: 23 | G10: 24 | H10: 25 | I10: 26 | J10: 27 | K10: 28 | L10: 29 | M10: 30 | N10: 31 | O10: 32 | P10: 33 | Q10: 34 | R10: 35 | S10: 36
A11: 1 | T11: =SUM(B11:S11) -> 0
A12: 2 | T12: =SUM(B12:S12) -> 0
A13: 3 | T13: =SUM(B13:S13) -> 0
A14: 4 | T14: =SUM(B14:S14) -> 0
A15: 5 | T15: =SUM(B15:S15) -> 0
A16: 6 | T16: =SUM(B16:S16) -> 0
A17: Sub | T17: =SUM(B17:S17) -> 0
B18: =SUM(B11:B17) -> 0 | C18: =SUM(C11:C17) -> 0 | D18: =SUM(D11:D17) -> 0 | E18: =SUM(E11:E17) -> 0 | F18: =SUM(F11:F17) -> 0 | G18: =SUM(G11:G17) -> 0 | H18: =SUM(H11:H17) -> 0 | I18: =SUM(I11:I17) -> 0 | ... T18: =SUM(T11:T17) -> 0
A20: Bowler | B20: 25/26 Season | C20: Paid | D20: Balance | F20: Rooms | G20: Paid | H20: Balance
A21: Hillary Chambers | B21: =(36*30)+10 -> 1090 | C21: =+T2+T11 -> 1090 | D21: =+B21-C21 -> 0 | F21: 0 | G21: 0 | H21: =+F21-G21 -> 0
A22: Holly Danielsen | B22: =(36*30)+10 -> 1090 | C22: =+T3+T12 -> 810 | D22: =+B22-C22 -> 280 | F22: 0 | G22: 0 | H22: =+F22-G22 -> 0
A23: Alexandria Yorgensen | B23: =(36*30)+10 -> 1090 | C23: =+T4+T13 -> 520 | D23: =+B23-C23 -> 570 | F23: 0 | G23: 0 | H23: =+F23-G23 -> 0
A24: Christopher Yazzie | B24: =(36*30)+10 -> 1090 | C24: =+T5+T14 -> 640 | D24: =+B24-C24 -> 450 | F24: 0 | G24: 0 | H24: =+F24-G24 -> 0
A25: 5 | B25: =(36*30)+10 -> 1090 | C25: =+T6+T15 -> 60 | D25: =+B25-C25 -> 1030 | F25: 0 | G25: 0 | H25: =+F25-G25 -> 0
A26: 6 | B26: =(36*30)+10 -> 1090 | C26: =+T7+T18 -> 0 | D26: =+B26-C26 -> 1090 | F26: 0 | G26: 0 | H26: =+F26-G26 -> 0
F27: Total | G27: =SUM(G21:G26) -> 0

Sheet 4
A1: 0 | B1: 1 | C1: 2 | D1: 3 | E1: 4 | F1: 5 | G1: 6 | H1: 7 | I1: 8 | J1: 9 | K1: 10 | L1: 11 | M1: 12 | N1: 13 | O1: 14 | P1: 15 | Q1: 16 | R1: 17 | S1: 18
A2: Sandra Yorgensen | C2: 30 | D2: 30 | E2: 30 | G2: 60 | I2: 120 | N2: 30 | O2: 30 | P2: 30 | Q2: 60 | R2: 60 | S2: 30 | T2: =SUM(B2:S2) -> 510
A3: Xelan Contreas | T3: =SUM(B3:S3) -> 0
A4: Brooke-Lynn Alspaugh | B4: 30 | C4: 30 | D4: 30 | G4: 60 | H4: 60 | I4: 60 | J4: 0 | K4: 30 | L4: 30 | N4: 30 | O4: 30 | P4: 30 | Q4: 90 | S4: 60 | T4: =SUM(B4:S4) -> 570
A5: Brett Marowelli | B5: 30 | C5: 30 | D5: 30 | G5: 60 | H5: 60 | I5: 60 | J5: 0 | K5: 30 | L5: 30 | N5: 30 | O5: 30 | P5: 30 | Q5: 90 | S5: 60 | T5: =SUM(B5:S5) -> 570
A6: Shawn Yorgensen | D6: 0 | N6: 30 | O6: 120 | P6: 30 | Q6: 60 | R6: 60 | S6: 30 | T6: =SUM(B6:S6) -> 330
A7: Melissa Adkins | B7: 30 | C7: 30 | D7: 30 | G7: 120 | I7: 120 | K7: 0 | L7: 60 | O7: 30 | T7: =SUM(B7:S7) -> 420
A8: Sub | T8: =SUM(B8:S8) -> 0
